Workbook
Name gongfuKPI: '汇报-gongfu'!$Y$184
Name gongfu付费arppu: '汇报-gongfu'!$A$259
Name gongfu付费贡献组成: '汇报-gongfu'!$A$211
Name gongfu付费基本: '汇报-gongfu'!$A$118
Name gongfu付费率: '汇报-gongfu'!$A$332
Name gongfu付费用户组成: '汇报-gongfu'!$A$166
Name gongfu活跃构成: '汇报-gongfu'!$A$72
Name gongfu活跃基本: '汇报-gongfu'!$A$29
Name gongfu页首: '汇报-gongfu'!$A$1
Name gongfu游戏习惯: '汇报-gongfu'!$A$384
Name gongfu有效活跃: '汇报-gongfu'!$A$359
Name huaKPI: '汇报-hua'!$Y$182
Name hua付费arppu: '汇报-hua'!$A$256
Name hua付费贡献组成: '汇报-hua'!$A$208
Name hua付费基本: '汇报-hua'!$A$117
Name hua付费率: '汇报-hua'!$A$329
Name hua付费用户组成: '汇报-hua'!$A$164
Name hua活跃构成: '汇报-hua'!$A$71
Name hua活跃基本: '汇报-hua'!$A$30
Name hua页首: '汇报-hua'!$A$1
Name hua游戏习惯: '汇报-hua'!$A$381
Name hua有效活跃: '汇报-hua'!$A$358
Name jlKPI: '汇报-jl'!$Z$181
Name jl付费arppu: '汇报-jl'!$A$257
Name jl付费贡献组成: '汇报-jl'!$A$209
Name jl付费基本: '汇报-jl'!$A$117
Name jl付费率: '汇报-jl'!$A$330
Name jl付费用户组成: '汇报-jl'!$A$163
Name jl活跃构成: '汇报-jl'!$A$73
Name jl活跃基本: '汇报-jl'!$A$29
Name jl页首: '汇报-jl'!$A$1
Name jl游戏习惯: '汇报-jl'!$A$382
Name jl有效活跃: '汇报-jl'!$A$358
Name seer2KPI: '汇报-seer2'!$Y$185
Name seer2付费arppu: '汇报-seer2'!$A$258
Name seer2付费贡献组成: '汇报-seer2'!$A$211
Name seer2付费基本: '汇报-seer2'!$A$117
Name seer2付费率: '汇报-seer2'!$A$331
Name seer2付费用户组成: '汇报-seer2'!$A$166
Name seer2活跃构成: '汇报-seer2'!$A$73
Name seer2活跃基本: '汇报-seer2'!$A$30
Name seer2页首: '汇报-seer2'!$A$1
Name seer2游戏习惯: '汇报-seer2'!$A$384
Name seer2有效活跃: '汇报-seer2'!$A$359
Name seerKPI: '汇报-seer'!$Z$182
Name seer付费arppu: '汇报-seer'!$A$243
Name seer付费贡献组成: '汇报-seer'!$A$197
Name seer付费基本: '汇报-seer'!$A$106
Name seer付费率: '汇报-seer'!$A$316
Name seer付费用户组成: '汇报-seer'!$A$153
Name seer活跃构成: '汇报-seer'!$A$61
Name seer活跃基本: '汇报-seer'!$A$12
Name seer页首: '汇报-seer'!$A$1
Name seer游戏习惯: '汇报-seer'!$A$367
Name seer有效活跃: '汇报-seer'!$A$343
Name 创想兵团: '汇报-合作产品'!$B$26
Name 创想兵团KPI: '汇报-合作产品'!$AD$60
Name 海外产品: '汇报-合作产品'!$B$209
Name 合作产品部页首: '汇报-合作产品'!$A$1
Name 联运产品: '汇报-合作产品'!$B$125

Sheet 对比
A1: 用于比对数据中心（老）和数据分析平台（新）的月报数据，发现问题
A2: 1、 | B2: 新平台提供不含短信包月续费的包月收入
A3: 2、 | B3: 赛尔号历史转化新增付费用户的差异逐渐减小
A4: 3、 | B4: 5月前无数据的，有效活跃用户、PCU，ACU
A5: 4、 | B5: ACU，赛尔号的7,8月有问题
A6: 5、 | B6: 与活跃相关的，5月之前都有问题，最好能补全。
A7: 6、 | B7: 小花仙新平台偏小2%，原因为统计节点不同，原数据中心是偏大的，同、环比时可拿偏小值代替
BE9: =BE64/历史汇总!AY3 -> -0.00063082162
A10: 新 | B10: 旧 | BE10: =BE13/历史汇总!AY42 -> 7.6463239e-05
A11: 历史新 | B11: 历史汇总 | H11: 1 | I11: 2 | J11: 3 | K11: 4 | L11: 5 | M11: 6 | N11: 7 | O11: 8 | P11: 9 | Q11: 10 | R11: 11 | S11: 12 | T11: 13 | U11: 14 | V11: 15 | W11: 16 | X11: 17 | Y11: 18 | Z11: 19 | AA11: 20 | AB11: 21 | AC11: 22 | AD11: 23 | AE11: 24 | AF11: 25 | AG11: 26 | AH11: 27 | AI11: 28 | AJ11: 29 | AK11: 30 | AL11: 31 | AM11: 32 | AN11: 33 | AO11: 34 | AP11: 35 | AQ11: 36 | AR11: 37 | AS11: 38 | AT11: 39 | AU11: 40 | AV11: 41 | AW11: 42 | AX11: 43 | AY11: 44 | AZ11: 45 | BA11: 46 | BB11: 47 | BC11: 48 | BD11: 49 | BE11: 50 | BF11: 51
G12: 赛尔号 | H12: 2011-01 | I12: 2011-02 | J12: 2011-03 | K12: 2011-04 | L12: 2011-05 | M12: 2011-06 | N12: 2011-07 | O12: 2011-08 | P12: 2011-09 | Q12: 2011-10 | R12: 2011-11 | S12: 2011-12 | T12: 2012-01 | U12: 2012-02 | V12: 2012-03 | W12: 2012-04 | X12: 2012-05 | Y12: 2012-06 | Z12: 2012-07 | AA12: 2012-08 | AB12: 2012-09 | AC12: 2012-10 | AD12: 2012-11 | AE12: 2012-12 | AF12: 2013-01 | AG12: 2013-02 | AH12: 2013-03 | AI12: 2013-04 | AJ12: 2013-05 | AK12: 2013-06 | AL12: 2013-07 | AM12: 2013-08 | AN12: 2013-09 | AO12: 2013-10 | AP12: 2013-11 | AQ12: 2013-12 | AR12: 2014-01 | AS12: 2014-02 | AT12: 2014-03 | AU12: 2014-04 | AV12: 2014-05 | AW12: 2014-06 | AX12: 2014-07 | AY12: 2014-08 | AZ12: 2014-09 | BA12: 2014-10 | BB12: 2014-11 | BC12: 2014-12 | BD12: 2015-01 | BE12: 2015-02 | BF12: 2015-03
A13: !C | B13: !B | C13: 2 | D13: 42 | E13: =$A$11&$A$13&C13 -> 历史新!C2 | F13: =$B$11&$B$13&D13 -> 历史汇总!B42 | G13: 付费总额(元) | H13: =OFFSET(INDIRECT($E13),0,H$11)-OFFSET(INDIRECT($F13),0,H$11) -> 55480 | I13: =OFFSET(INDIRECT($E13),0,I$11)-OFFSET(INDIRECT($F13),0,I$11) -> 37630 | J13: =OFFSET(INDIRECT($E13),0,J$11)-OFFSET(INDIRECT($F13),0,J$11) -> 37720 | K13: =OFFSET(INDIRECT($E13),0,K$11)-OFFSET(INDIRECT($F13),0,K$11) -> 39680 | L13: =OFFSET(INDIRECT($E13),0,L$11)-OFFSET(INDIRECT($F13),0,L$11) -> 31590 | M13: =OFFSET(INDIRECT($E13),0,M$11)-OFFSET(INDIRECT($F13),0,M$11) -> 52070 | N13: =OFFSET(INDIRECT($E13),0,N$11)-OFFSET(INDIRECT($F13),0,N$11) -> 48180 | O13: =OFFSET(INDIRECT($E13),0,O$11)-OFFSET(INDIRECT($F13),0,O$11) -> 26230 | ... BF13: =OFFSET(INDIRECT($E13),0,BF$11)-OFFSET(INDIRECT($F13),0,BF$11) -> 8902157
C14: 3 | D14: 43 | E14: =$A$11&$A$13&C14 -> 历史新!C3 | F14: =$B$11&$B$13&D14 -> 历史汇总!B43 | G14: 付费总额(元)增长率 | H14: =OFFSET(INDIRECT($E14),0,H$11)-OFFSET(INDIRECT($F14),0,H$11) -> -0.0015 | I14: =OFFSET(INDIRECT($E14),0,I$11)-OFFSET(INDIRECT($F14),0,I$11) -> 0.0001 | J14: =OFFSET(INDIRECT($E14),0,J$11)-OFFSET(INDIRECT($F14),0,J$11) -> -0.0001 | K14: =OFFSET(INDIRECT($E14),0,K$11)-OFFSET(INDIRECT($F14),0,K$11) -> 0.0003 | L14: =OFFSET(INDIRECT($E14),0,L$11)-OFFSET(INDIRECT($F14),0,L$11) -> -0.0002 | M14: =OFFSET(INDIRECT($E14),0,M$11)-OFFSET(INDIRECT($F14),0,M$11) -> 0.0011 | N14: =OFFSET(INDIRECT($E14),0,N$11)-OFFSET(INDIRECT($F14),0,N$11) -> -0.0003 | O14: =OFFSET(INDIRECT($E14),0,O$11)-OFFSET(INDIRECT($F14),0,O$11) -> -0.0003 | ... BF14: =OFFSET(INDIRECT($E14),0,BF$11)-OFFSET(INDIRECT($F14),0,BF$11) -> -0.0815
C15: 4 | D15: 44 | E15: =$A$11&$A$13&C15 -> 历史新!C4 | F15: =$B$11&$B$13&D15 -> 历史汇总!B44 | G15: 付费用户数 | H15: =OFFSET(INDIRECT($E15),0,H$11)-OFFSET(INDIRECT($F15),0,H$11) -> 1828 | I15: =OFFSET(INDIRECT($E15),0,I$11)-OFFSET(INDIRECT($F15),0,I$11) -> 1626 | J15: =OFFSET(INDIRECT($E15),0,J$11)-OFFSET(INDIRECT($F15),0,J$11) -> 1618 | K15: =OFFSET(INDIRECT($E15),0,K$11)-OFFSET(INDIRECT($F15),0,K$11) -> 1517 | L15: =OFFSET(INDIRECT($E15),0,L$11)-OFFSET(INDIRECT($F15),0,L$11) -> 1353 | M15: =OFFSET(INDIRECT($E15),0,M$11)-OFFSET(INDIRECT($F15),0,M$11) -> 2456 | N15: =OFFSET(INDIRECT($E15),0,N$11)-OFFSET(INDIRECT($F15),0,N$11) -> 1898 | O15: =OFFSET(INDIRECT($E15),0,O$11)-OFFSET(INDIRECT($F15),0,O$11) -> 1112 | ... BF15: =OFFSET(INDIRECT($E15),0,BF$11)-OFFSET(INDIRECT($F15),0,BF$11) -> 146274
C16: 5 | D16: 45 | E16: =$A$11&$A$13&C16 -> 历史新!C5 | F16: =$B$11&$B$13&D16 -> 历史汇总!B45 | G16: 付费用户数增长率 | H16: =OFFSET(INDIRECT($E16),0,H$11)-OFFSET(INDIRECT($F16),0,H$11) -> -0.004 | I16: =OFFSET(INDIRECT($E16),0,I$11)-OFFSET(INDIRECT($F16),0,I$11) -> 0.0002 | J16: =OFFSET(INDIRECT($E16),0,J$11)-OFFSET(INDIRECT($F16),0,J$11) -> 0.0002 | K16: =OFFSET(INDIRECT($E16),0,K$11)-OFFSET(INDIRECT($F16),0,K$11) -> 0 | L16: =OFFSET(INDIRECT($E16),0,L$11)-OFFSET(INDIRECT($F16),0,L$11) -> 0 | M16: =OFFSET(INDIRECT($E16),0,M$11)-OFFSET(INDIRECT($F16),0,M$11) -> 0.002 | N16: =OFFSET(INDIRECT($E16),0,N$11)-OFFSET(INDIRECT($F16),0,N$11) -> -0.0008 | O16: =OFFSET(INDIRECT($E16),0,O$11)-OFFSET(INDIRECT($F16),0,O$11) -> -0.0007 | ... BF16: =OFFSET(INDIRECT($E16),0,BF$11)-OFFSET(INDIRECT($F16),0,BF$11) -> -0.0991
C17: 6 | D17: 56 | E17: =$A$11&$A$13&C17 -> 历史新!C6 | F17: =$B$11&$B$13&D17 -> 历史汇总!B56 | G17: arppu值 | H17: =OFFSET(INDIRECT($E17),0,H$11)-OFFSET(INDIRECT($F17),0,H$11) -> -0.0201 | I17: =OFFSET(INDIRECT($E17),0,I$11)-OFFSET(INDIRECT($F17),0,I$11) -> -0.0278 | J17: =OFFSET(INDIRECT($E17),0,J$11)-OFFSET(INDIRECT($F17),0,J$11) -> -0.0405 | K17: =OFFSET(INDIRECT($E17),0,K$11)-OFFSET(INDIRECT($F17),0,K$11) -> -0.0236 | L17: =OFFSET(INDIRECT($E17),0,L$11)-OFFSET(INDIRECT($F17),0,L$11) -> -0.0275 | M17: =OFFSET(INDIRECT($E17),0,M$11)-OFFSET(INDIRECT($F17),0,M$11) -> -0.0562 | N17: =OFFSET(INDIRECT($E17),0,N$11)-OFFSET(INDIRECT($F17),0,N$11) -> -0.0365 | O17: =OFFSET(INDIRECT($E17),0,O$11)-OFFSET(INDIRECT($F17),0,O$11) -> -0.0229 | ... BF17: =OFFSET(INDIRECT($E17),0,BF$11)-OFFSET(INDIRECT($F17),0,BF$11) -> 60.86
C18: 7 | D18: 57 | E18: =$A$11&$A$13&C18 -> 历史新!C7 | F18: =$B$11&$B$13&D18 -> 历史汇总!B57 | G18: arppu值增长率 | H18: =OFFSET(INDIRECT($E18),0,H$11)-OFFSET(INDIRECT($F18),0,H$11) -> 0.0032 | I18: =OFFSET(INDIRECT($E18),0,I$11)-OFFSET(INDIRECT($F18),0,I$11) -> -0.0002 | J18: =OFFSET(INDIRECT($E18),0,J$11)-OFFSET(INDIRECT($F18),0,J$11) -> -0.0003 | K18: =OFFSET(INDIRECT($E18),0,K$11)-OFFSET(INDIRECT($F18),0,K$11) -> 0.0004 | L18: =OFFSET(INDIRECT($E18),0,L$11)-OFFSET(INDIRECT($F18),0,L$11) -> -0.0001 | M18: =OFFSET(INDIRECT($E18),0,M$11)-OFFSET(INDIRECT($F18),0,M$11) -> -0.0009 | N18: =OFFSET(INDIRECT($E18),0,N$11)-OFFSET(INDIRECT($F18),0,N$11) -> 0.0007 | O18: =OFFSET(INDIRECT($E18),0,O$11)-OFFSET(INDIRECT($F18),0,O$11) -> 0.0002 | ... BF18: =OFFSET(INDIRECT($E18),0,BF$11)-OFFSET(INDIRECT($F18),0,BF$11) -> 0.0194
C19: 8 | D19: 59 | E19: =$A$11&$A$13&C19 -> 历史新!C8 | F19: =$B$11&$B$13&D19 -> 历史汇总!B59 | G19: 包月支付总额(不含短信包月续费) | H19: =OFFSET(INDIRECT($E19),0,H$11)-OFFSET(INDIRECT($F19),0,H$11) -> -14488650 | I19: =OFFSET(INDIRECT($E19),0,I$11)-OFFSET(INDIRECT($F19),0,I$11) -> -10755380 | J19: =OFFSET(INDIRECT($E19),0,J$11)-OFFSET(INDIRECT($F19),0,J$11) -> -7243730 | K19: =OFFSET(INDIRECT($E19),0,K$11)-OFFSET(INDIRECT($F19),0,K$11) -> -8883210 | L19: =OFFSET(INDIRECT($E19),0,L$11)-OFFSET(INDIRECT($F19),0,L$11) -> -7590000 | M19: =OFFSET(INDIRECT($E19),0,M$11)-OFFSET(INDIRECT($F19),0,M$11) -> -6791710 | N19: =OFFSET(INDIRECT($E19),0,N$11)-OFFSET(INDIRECT($F19),0,N$11) -> -6951950 | O19: =OFFSET(INDIRECT($E19),0,O$11)-OFFSET(INDIRECT($F19),0,O$11) -> -5385760 | ... BF19: =OFFSET(INDIRECT($E19),0,BF$11)-OFFSET(INDIRECT($F19),0,BF$11) -> 2024280
C20: 9 | D20: 60 | E20: =$A$11&$A$13&C20 -> 历史新!C9 | F20: =$B$11&$B$13&D20 -> 历史汇总!B60 | G20: 包月支付总额(不含短信包月续费)增长率 | H20: =OFFSET(INDIRECT($E20),0,H$11)-OFFSET(INDIRECT($F20),0,H$11) -> -0.0092 | I20: =OFFSET(INDIRECT($E20),0,I$11)-OFFSET(INDIRECT($F20),0,I$11) -> 0.2577 | J20: =OFFSET(INDIRECT($E20),0,J$11)-OFFSET(INDIRECT($F20),0,J$11) -> 0.3265 | K20: =OFFSET(INDIRECT($E20),0,K$11)-OFFSET(INDIRECT($F20),0,K$11) -> -0.2263 | L20: =OFFSET(INDIRECT($E20),0,L$11)-OFFSET(INDIRECT($F20),0,L$11) -> 0.1456 | M20: =OFFSET(INDIRECT($E20),0,M$11)-OFFSET(INDIRECT($F20),0,M$11) -> 0.1052 | N20: =OFFSET(INDIRECT($E20),0,N$11)-OFFSET(INDIRECT($F20),0,N$11) -> -0.0236 | O20: =OFFSET(INDIRECT($E20),0,O$11)-OFFSET(INDIRECT($F20),0,O$11) -> 0.2253 | ... BF20: =OFFSET(INDIRECT($E20),0,BF$11)-OFFSET(INDIRECT($F20),0,BF$11) -> 0.0805
C21: 10 | D21: 61 | E21: =$A$11&$A$13&C21 -> 历史新!C10 | F21: =$B$11&$B$13&D21 -> 历史汇总!B61 | G21: 包月支付用户数(不含短信包月续费) | H21: =OFFSET(INDIRECT($E21),0,H$11)-OFFSET(INDIRECT($F21),0,H$11) -> -706101 | I21: =OFFSET(INDIRECT($E21),0,I$11)-OFFSET(INDIRECT($F21),0,I$11) -> -567022 | J21: =OFFSET(INDIRECT($E21),0,J$11)-OFFSET(INDIRECT($F21),0,J$11) -> -449315 | K21: =OFFSET(INDIRECT($E21),0,K$11)-OFFSET(INDIRECT($F21),0,K$11) -> -446538 | L21: =OFFSET(INDIRECT($E21),0,L$11)-OFFSET(INDIRECT($F21),0,L$11) -> -395479 | M21: =OFFSET(INDIRECT($E21),0,M$11)-OFFSET(INDIRECT($F21),0,M$11) -> -411101 | N21: =OFFSET(INDIRECT($E21),0,N$11)-OFFSET(INDIRECT($F21),0,N$11) -> -398957 | O21: =OFFSET(INDIRECT($E21),0,O$11)-OFFSET(INDIRECT($F21),0,O$11) -> -317935 | ... BF21: =OFFSET(INDIRECT($E21),0,BF$11)-OFFSET(INDIRECT($F21),0,BF$11) -> 71586
C22: 11 | D22: 62 | E22: =$A$11&$A$13&C22 -> 历史新!C11 | F22: =$B$11&$B$13&D22 -> 历史汇总!B62 | G22: 包月支付用户数(不含短信包月续费)增长率 | H22: =OFFSET(INDIRECT($E22),0,H$11)-OFFSET(INDIRECT($F22),0,H$11) -> 0.1055 | I22: =OFFSET(INDIRECT($E22),0,I$11)-OFFSET(INDIRECT($F22),0,I$11) -> 0.197 | J22: =OFFSET(INDIRECT($E22),0,J$11)-OFFSET(INDIRECT($F22),0,J$11) -> 0.2076 | K22: =OFFSET(INDIRECT($E22),0,K$11)-OFFSET(INDIRECT($F22),0,K$11) -> 0.0062 | L22: =OFFSET(INDIRECT($E22),0,L$11)-OFFSET(INDIRECT($F22),0,L$11) -> 0.1143 | M22: =OFFSET(INDIRECT($E22),0,M$11)-OFFSET(INDIRECT($F22),0,M$11) -> -0.0395 | N22: =OFFSET(INDIRECT($E22),0,N$11)-OFFSET(INDIRECT($F22),0,N$11) -> 0.0295 | O22: =OFFSET(INDIRECT($E22),0,O$11)-OFFSET(INDIRECT($F22),0,O$11) -> 0.2031 | ... BF22: =OFFSET(INDIRECT($E22),0,BF$11)-OFFSET(INDIRECT($F22),0,BF$11) -> 0.0409
C23: 12 | D23: 63 | E23: =$A$11&$A$13&C23 -> 历史新!C12 | F23: =$B$11&$B$13&D23 -> 历史汇总!B63 | G23: 包月支付arppu值 | H23: =OFFSET(INDIRECT($E23),0,H$11)-OFFSET(INDIRECT($F23),0,H$11) -> -20.5192 | I23: =OFFSET(INDIRECT($E23),0,I$11)-OFFSET(INDIRECT($F23),0,I$11) -> -18.9682 | J23: =OFFSET(INDIRECT($E23),0,J$11)-OFFSET(INDIRECT($F23),0,J$11) -> -16.1217 | K23: =OFFSET(INDIRECT($E23),0,K$11)-OFFSET(INDIRECT($F23),0,K$11) -> -19.8935 | L23: =OFFSET(INDIRECT($E23),0,L$11)-OFFSET(INDIRECT($F23),0,L$11) -> -19.1919 | M23: =OFFSET(INDIRECT($E23),0,M$11)-OFFSET(INDIRECT($F23),0,M$11) -> -16.5208 | N23: =OFFSET(INDIRECT($E23),0,N$11)-OFFSET(INDIRECT($F23),0,N$11) -> -17.4253 | O23: =OFFSET(INDIRECT($E23),0,O$11)-OFFSET(INDIRECT($F23),0,O$11) -> -16.9398 | ... BF23: =OFFSET(INDIRECT($E23),0,BF$11)-OFFSET(INDIRECT($F23),0,BF$11) -> 28.28
C24: 13 | D24: 64 | E24: =$A$11&$A$13&C24 -> 历史新!C13 | F24: =$B$11&$B$13&D24 -> 历史汇总!B64 | G24: 包月支付arppu值增长率 | H24: =OFFSET(INDIRECT($E24),0,H$11)-OFFSET(INDIRECT($F24),0,H$11) -> -0.1283 | I24: =OFFSET(INDIRECT($E24),0,I$11)-OFFSET(INDIRECT($F24),0,I$11) -> 0.0756 | J24: =OFFSET(INDIRECT($E24),0,J$11)-OFFSET(INDIRECT($F24),0,J$11) -> 0.1501 | K24: =OFFSET(INDIRECT($E24),0,K$11)-OFFSET(INDIRECT($F24),0,K$11) -> -0.234 | L24: =OFFSET(INDIRECT($E24),0,L$11)-OFFSET(INDIRECT($F24),0,L$11) -> 0.0353 | M24: =OFFSET(INDIRECT($E24),0,M$11)-OFFSET(INDIRECT($F24),0,M$11) -> 0.1392 | N24: =OFFSET(INDIRECT($E24),0,N$11)-OFFSET(INDIRECT($F24),0,N$11) -> -0.0547 | O24: =OFFSET(INDIRECT($E24),0,O$11)-OFFSET(INDIRECT($F24),0,O$11) -> 0.0279 | ... BF24: =OFFSET(INDIRECT($E24),0,BF$11)-OFFSET(INDIRECT($F24),0,BF$11) -> 0.0382
C25: 14 | D25: 66 | E25: =$A$11&$A$13&C25 -> 历史新!C14 | F25: =$B$11&$B$13&D25 -> 历史汇总!B66 | G25: 按条支付总额 | H25: =OFFSET(INDIRECT($E25),0,H$11)-OFFSET(INDIRECT($F25),0,H$11) -> 0 | I25: =OFFSET(INDIRECT($E25),0,I$11)-OFFSET(INDIRECT($F25),0,I$11) -> 0 | J25: =OFFSET(INDIRECT($E25),0,J$11)-OFFSET(INDIRECT($F25),0,J$11) -> 0 | K25: =OFFSET(INDIRECT($E25),0,K$11)-OFFSET(INDIRECT($F25),0,K$11) -> 0 | L25: =OFFSET(INDIRECT($E25),0,L$11)-OFFSET(INDIRECT($F25),0,L$11) -> 0 | M25: =OFFSET(INDIRECT($E25),0,M$11)-OFFSET(INDIRECT($F25),0,M$11) -> 0 | N25: =OFFSET(INDIRECT($E25),0,N$11)-OFFSET(INDIRECT($F25),0,N$11) -> 0 | O25: =OFFSET(INDIRECT($E25),0,O$11)-OFFSET(INDIRECT($F25),0,O$11) -> 0 | ... BF25: =OFFSET(INDIRECT($E25),0,BF$11)-OFFSET(INDIRECT($F25),0,BF$11) -> 6683807
... C34: 23 | D34: 49 | E34: =$A$11&$A$13&C34 -> 历史新!C23 | F34: =$B$11&$B$13&D34 -> 历史汇总!B49 | G34: 回流付费用户数 | H34: =OFFSET(INDIRECT($E34),0,H$11)-OFFSET(INDIRECT($F34),0,H$11) -> -1912 | I34: =OFFSET(INDIRECT($E34),0,I$11)-OFFSET(INDIRECT($F34),0,I$11) -> -212 | J34: =OFFSET(INDIRECT($E34),0,J$11)-OFFSET(INDIRECT($F34),0,J$11) -> -142 | K34: =OFFSET(INDIRECT($E34),0,K$11)-OFFSET(INDIRECT($F34),0,K$11) -> -218 | L34: =OFFSET(INDIRECT($E34),0,L$11)-OFFSET(INDIRECT($F34),0,L$11) -> -113 | M34: =OFFSET(INDIRECT($E34),0,M$11)-OFFSET(INDIRECT($F34),0,M$11) -> 323 | N34: =OFFSET(INDIRECT($E34),0,N$11)-OFFSET(INDIRECT($F34),0,N$11) -> -396 | O34: =OFFSET(INDIRECT($E34),0,O$11)-OFFSET(INDIRECT($F34),0,O$11) -> -321 | ... BF34: =OFFSET(INDIRECT($E34),0,BF$11)-OFFSET(INDIRECT($F34),0,BF$11) -> 38913
C35: 24 | G35: 新增用户中的付费用户数
C36: 25 | G36: 留存用户中的付费用户数
C37: 26 | G37: 回流用户中的付费用户数
C38: 27 | G38: 付费率
C39: 28 | G39: 付费率增长率
C40: 29 | G40: 新增用户付费率
C41: 30 | G41: 留存用户付费率
C42: 31 | G42: 回流用户付费率
C43: 32 | D43: 50 | E43: =$A$11&$A$13&C43 -> 历史新!C32 | F43: =$B$11&$B$13&D43 -> 历史汇总!B50 | G43: 纯新增付费用户占比 | H43: =OFFSET(INDIRECT($E43),0,H$11)-OFFSET(INDIRECT($F43),0,H$11) -> 0.0017 | I43: =OFFSET(INDIRECT($E43),0,I$11)-OFFSET(INDIRECT($F43),0,I$11) -> 0.0009 | J43: =OFFSET(INDIRECT($E43),0,J$11)-OFFSET(INDIRECT($F43),0,J$11) -> 0.0033 | K43: =OFFSET(INDIRECT($E43),0,K$11)-OFFSET(INDIRECT($F43),0,K$11) -> 0.0008 | L43: =OFFSET(INDIRECT($E43),0,L$11)-OFFSET(INDIRECT($F43),0,L$11) -> 0.0008 | M43: =OFFSET(INDIRECT($E43),0,M$11)-OFFSET(INDIRECT($F43),0,M$11) -> 0.0015 | N43: =OFFSET(INDIRECT($E43),0,N$11)-OFFSET(INDIRECT($F43),0,N$11) -> 0.0013 | O43: =OFFSET(INDIRECT($E43),0,O$11)-OFFSET(INDIRECT($F43),0,O$11) -> 0.0007 | ... BF43: =OFFSET(INDIRECT($E43),0,BF$11)-OFFSET(INDIRECT($F43),0,BF$11) -> 0.1379
C44: 33 | D44: 51 | E44: =$A$11&$A$13&C44 -> 历史新!C33 | F44: =$B$11&$B$13&D44 -> 历史汇总!B51 | G44: 历史转化新增付费用户占比 | H44: =OFFSET(INDIRECT($E44),0,H$11)-OFFSET(INDIRECT($F44),0,H$11) -> -0.0034 | I44: =OFFSET(INDIRECT($E44),0,I$11)-OFFSET(INDIRECT($F44),0,I$11) -> -0.0014 | J44: =OFFSET(INDIRECT($E44),0,J$11)-OFFSET(INDIRECT($F44),0,J$11) -> -0.0038 | K44: =OFFSET(INDIRECT($E44),0,K$11)-OFFSET(INDIRECT($F44),0,K$11) -> -0.0011 | L44: =OFFSET(INDIRECT($E44),0,L$11)-OFFSET(INDIRECT($F44),0,L$11) -> -0.0011 | M44: =OFFSET(INDIRECT($E44),0,M$11)-OFFSET(INDIRECT($F44),0,M$11) -> -0.0011 | N44: =OFFSET(INDIRECT($E44),0,N$11)-OFFSET(INDIRECT($F44),0,N$11) -> -0.002 | O44: =OFFSET(INDIRECT($E44),0,O$11)-OFFSET(INDIRECT($F44),0,O$11) -> -0.002 | ... BF44: =OFFSET(INDIRECT($E44),0,BF$11)-OFFSET(INDIRECT($F44),0,BF$11) -> 0.1735
C45: 34 | D45: 52 | E45: =$A$11&$A$13&C45 -> 历史新!C34 | F45: =$B$11&$B$13&D45 -> 历史汇总!B52 | G45: 连续两月付费用户占比 | H45: =OFFSET(INDIRECT($E45),0,H$11)-OFFSET(INDIRECT($F45),0,H$11) -> 0.0043 | I45: =OFFSET(INDIRECT($E45),0,I$11)-OFFSET(INDIRECT($F45),0,I$11) -> 0.0013 | J45: =OFFSET(INDIRECT($E45),0,J$11)-OFFSET(INDIRECT($F45),0,J$11) -> 0.0013 | K45: =OFFSET(INDIRECT($E45),0,K$11)-OFFSET(INDIRECT($F45),0,K$11) -> 0.0013 | L45: =OFFSET(INDIRECT($E45),0,L$11)-OFFSET(INDIRECT($F45),0,L$11) -> 0.0013 | M45: =OFFSET(INDIRECT($E45),0,M$11)-OFFSET(INDIRECT($F45),0,M$11) -> 0.0006 | N45: =OFFSET(INDIRECT($E45),0,N$11)-OFFSET(INDIRECT($F45),0,N$11) -> 0.0026 | O45: =OFFSET(INDIRECT($E45),0,O$11)-OFFSET(INDIRECT($F45),0,O$11) -> 0.0029 | ... BF45: =OFFSET(INDIRECT($E45),0,BF$11)-OFFSET(INDIRECT($F45),0,BF$11) -> 0.4358
C46: 35 | D46: 53 | E46: =$A$11&$A$13&C46 -> 历史新!C35 | F46: =$B$11&$B$13&D46 -> 历史汇总!B53 | G46: 回流付费用户占比 | H46: =OFFSET(INDIRECT($E46),0,H$11)-OFFSET(INDIRECT($F46),0,H$11) -> -0.0026 | I46: =OFFSET(INDIRECT($E46),0,I$11)-OFFSET(INDIRECT($F46),0,I$11) -> -0.0009 | J46: =OFFSET(INDIRECT($E46),0,J$11)-OFFSET(INDIRECT($F46),0,J$11) -> -0.001 | K46: =OFFSET(INDIRECT($E46),0,K$11)-OFFSET(INDIRECT($F46),0,K$11) -> -0.0011 | L46: =OFFSET(INDIRECT($E46),0,L$11)-OFFSET(INDIRECT($F46),0,L$11) -> -0.0009 | M46: =OFFSET(INDIRECT($E46),0,M$11)-OFFSET(INDIRECT($F46),0,M$11) -> -0.001 | N46: =OFFSET(INDIRECT($E46),0,N$11)-OFFSET(INDIRECT($F46),0,N$11) -> -0.002 | O46: =OFFSET(INDIRECT($E46),0,O$11)-OFFSET(INDIRECT($F46),0,O$11) -> -0.0016 | ... BF46: =OFFSET(INDIRECT($E46),0,BF$11)-OFFSET(INDIRECT($F46),0,BF$11) -> 0.266
C47: 36 | G47: 纯新增付费用户付费额
C48: 37 | G48: 历史转化新增付费用户付费额
C49: 38 | G49: 连续两月付费用户付费额
...

Sheet 历史汇总
A1: 赛尔号 | B1: =TEXT(DATE(LEFT(B2,4),RIGHT(B2,2),1),"yyyymm") -> 201101 | C1: =TEXT(DATE(LEFT(C2,4),RIGHT(C2,2),1),"yyyymm") -> 201102 | D1: =TEXT(DATE(LEFT(D2,4),RIGHT(D2,2),1),"yyyymm") -> 201103 | E1: =TEXT(DATE(LEFT(E2,4),RIGHT(E2,2),1),"yyyymm") -> 201104 | F1: =TEXT(DATE(LEFT(F2,4),RIGHT(F2,2),1),"yyyymm") -> 201105 | G1: =TEXT(DATE(LEFT(G2,4),RIGHT(G2,2),1),"yyyymm") -> 201106 | H1: =TEXT(DATE(LEFT(H2,4),RIGHT(H2,2),1),"yyyymm") -> 201107 | I1: =TEXT(DATE(LEFT(I2,4),RIGHT(I2,2),1),"yyyymm") -> 201108 | ... BC1: =TEXT(DATE(LEFT(BC2,4),RIGHT(BC2,2),1),"yyyymm") -> 201506
A2: 活跃在线情况 | B2: 201101 | C2: 201102 | D2: 201103 | E2: 201104 | F2: 201105 | G2: 201106 | H2: 201107 | I2: 201108 | J2: 201109 | K2: 201110 | L2: 201111 | M2: 201112 | N2: 201201 | O2: 201202 | P2: 201203 | Q2: 201204 | R2: 201205 | S2: 201206 | T2: 201207 | U2: 201208 | V2: 201209 | W2: 201210 | X2: 201211 | Y2: 201212 | Z2: 201301 | AA2: 201302 | AB2: 201303 | AC2: 201304 | AD2: 201305 | AE2: 201306 | AF2: 201307 | AG2: 201308 | AH2: 201309 | AI2: 201310 | AJ2: 201311 | AK2: 201312 | AL2: 201401 | AM2: 201402 | AN2: 201403 | AO2: 201404 | AP2: 201405 | AQ2: 201406 | AR2: 201407 | AS2: 201408 | AT2: 201409 | AU2: 201410 | AV2: 201411 | AW2: 201412 | AX2: 201501 | AY2: 201502 | AZ2: 201503 | BA2: 201504 | BB2: 201505 | BC2: 201506
A3: 活跃用户 | B3: 10679060 | C3: 9880147 | D3: 8087431 | E3: 8271173 | F3: 7580424 | G3: 7591640 | H3: 8898732 | I3: 8913903 | J3: 7176807 | K3: 7341309 | L3: 5816303 | M3: 6110993 | N3: 11032476 | O3: 9009967 | P3: 8269799 | Q3: 9729462 | R3: 8214876 | S3: 9116872 | T3: 10387046 | U3: 10301822 | V3: 7158214 | W3: 7540606 | X3: 5833153 | Y3: 6523281 | Z3: 7494097 | AA3: 9061604 | AB3: 7759770 | AC3: 7398010 | AD3: 7579863 | AE3: 9377764 | AF3: 13230360 | AG3: 11903660 | AH3: 8291649 | AI3: 8623420 | AJ3: 7117115 | AK3: 6022014 | AL3: 8290643 | AM3: 7034277 | AN3: 6390210 | AO3: 6110147 | AP3: 6648997 | AQ3: 9035146 | AR3: 12920754 | AS3: 11016505 | AT3: 6952463 | AU3: 7600303 | AV3: 6260587 | AW3: 5351572 | AX3: 6044284 | AY3: 7797767 | AZ3: 5673575
A4: 活跃用户增长率 | B4: 0.2765 | C4: -0.0748 | D4: -0.1814 | E4: 0.0227 | F4: -0.0835 | G4: 0.0015 | H4: 0.1722 | I4: 0.0017 | J4: -0.1949 | K4: 0.0229 | L4: -0.2077 | M4: 0.0507 | N4: 0 | O4: -0.1833 | P4: -0.0821 | Q4: 0.1765 | R4: -0.1557 | S4: 0.1098 | T4: 0.1393 | U4: -0.0082 | V4: -0.3052 | W4: 0.0534 | X4: -0.2264 | Y4: 0.1183 | Z4: 0.1488 | AA4: 0.2092 | AB4: -0.1437 | AC4: -0.0466 | AD4: 0.0246 | AE4: 0.2372 | AF4: 0.4108 | AG4: -0.1003 | AH4: -0.3034 | AI4: 0.04 | AJ4: -0.1747 | AK4: -0.1539 | AL4: 0.3767 | AM4: -0.1515 | AN4: -0.0916 | AO4: -0.0438 | AP4: 0.0882 | AQ4: 0.3589 | AR4: 0.4301 | AS4: -0.1474 | AT4: -0.3689 | AU4: 0.0932 | AV4: -0.1763 | AW4: -0.1452 | AX4: 0.1294 | AY4: 0.2901 | AZ4: -0.2724
A5: 有效活跃用户 | B5: 0 | C5: 6015987 | D5: 4729044 | E5: 4816678 | F5: 4523249 | G5: 4370334 | H5: 5247085 | I5: 5061189 | J5: 3893732 | K5: 3871730 | L5: 2871527 | M5: 2938432 | N5: 5600910 | O5: 4411513 | P5: 3908241 | Q5: 4658527 | R5: 3969112 | S5: 4665221 | T5: 5669060 | U5: 5265849 | V5: 3438885 | W5: 3617068 | X5: 2715457 | Y5: 3203918 | Z5: 3707141 | AA5: 4676058 | AB5: 3691747 | AC5: 3606194 | AD5: 3783049 | AE5: 4826590 | AF5: 7060016 | AG5: 5992233 | AH5: 3839386 | AI5: 3906883 | AJ5: 3130482 | AK5: 2706326 | AL5: 3838640 | AM5: 3157635 | AN5: 2838728 | AO5: 2566242 | AP5: 2824955 | AQ5: 4402011 | AR5: 6475739 | AS5: 4936778 | AT5: 2664554 | AU5: 2805731 | AV5: 2351833 | AW5: 2013640 | AX5: 2294364 | AY5: 2920420 | AZ5: 2193193
A6: 有效活跃用户增长率 | B6: 0 | C6: 0 | D6: -0.2139 | E6: 0.0185 | F6: -0.0609 | G6: -0.0338 | H6: 0.2006 | I6: -0.0354 | J6: -0.2307 | K6: -0.0057 | L6: -0.2583 | M6: 0.0233 | N6: 0 | O6: -0.2124 | P6: -0.1141 | Q6: 0.192 | R6: -0.148 | S6: 0.1754 | T6: 0.2152 | U6: -0.0711 | V6: -0.3469 | W6: 0.0518 | X6: -0.2493 | Y6: 0.1799 | Z6: 0.1571 | AA6: 0.2614 | AB6: -0.2105 | AC6: -0.0232 | AD6: 0.049 | AE6: 0.2758 | AF6: 0.4627 | AG6: -0.1512 | AH6: -0.3593 | AI6: 0.0176 | AJ6: -0.1987 | AK6: -0.1355 | AL6: 0.4184 | AM6: -0.1774 | AN6: -0.101 | AO6: -0.096 | AP6: 0.1008 | AQ6: 0.5583 | AR6: 0.4711 | AS6: -0.2377 | AT6: -0.4603 | AU6: 0.053 | AV6: -0.1618 | AW6: -0.1438 | AX6: 0.1394 | AY6: 0.2729 | AZ6: -0.249
A7: 新增活跃用户占比 | B7: 0.2955 | C7: 0.2519 | D7: 0.2089 | E7: 0.2068 | F7: 0.1944 | G7: 0.1997 | H7: 0.2618 | I7: 0.2904 | J7: 0.2475 | K7: 0.2412 | L7: 0.163 | M7: 0.2425 | N7: 0.4347 | O7: 0.3664 | P7: 0.3695 | Q7: 0.4251 | R7: 0.362 | S7: 0.3727 | T7: 0.4446 | U7: 0.4552 | V7: 0.3719 | W7: 0.3941 | X7: 0.3566 | Y7: 0.3863 | Z7: 0.4094 | AA7: 0.4537 | AB7: 0.4153 | AC7: 0.3975 | AD7: 0.3842 | AE7: 0.4343 | AF7: 0.5026 | AG7: 0.4434 | AH7: 0.3901 | AI7: 0.4062 | AJ7: 0.3794 | AK7: 0.3767 | AL7: 0.4524 | AM7: 0.4249 | AN7: 0.4301 | AO7: 0.4322 | AP7: 0.4603 | AQ7: 0.5485 | AR7: 0.5703 | AS7: 0.5225 | AT7: 0.4665 | AU7: 0.4906 | AV7: 0.4642 | AW7: 0.4488 | AX7: 0.4823 | AY7: 0.5441 | AZ7: 0.4991
A8: 留存用户占比 | B8: 0.5409 | C8: 0.6403 | D8: 0.6846 | E8: 0.6395 | F8: 0.6748 | G8: 0.6495 | H8: 0.5669 | I8: 0.5882 | J8: 0.6326 | K8: 0.5947 | L8: 0.6573 | M8: 0.5571 | N8: 0.3627 | O8: 0.5326 | P8: 0.5002 | Q8: 0.436 | R8: 0.5229 | S8: 0.4657 | T8: 0.4272 | U8: 0.4299 | V8: 0.5127 | W8: 0.4425 | X8: 0.4951 | Y8: 0.4135 | Z8: 0.3987 | AA8: 0.3769 | AB8: 0.4327 | AC8: 0.44 | AD8: 0.4473 | AE8: 0.3858 | AF8: 0.3471 | AG8: 0.4484 | AH8: 0.4859 | AI8: 0.4311 | AJ8: 0.4661 | AK8: 0.4522 | AL8: 0.3377 | AM8: 0.4286 | AN8: 0.3963 | AO8: 0.4027 | AP8: 0.3708 | AQ8: 0.3052 | AR8: 0.3045 | AS8: 0.3827 | AT8: 0.4194 | AU8: 0.349 | AV8: 0.3887 | AW8: 0.386 | AX8: 0.3304 | AY8: 0.2837 | AZ8: 0.3574
A9: 回流用户占比 | B9: 0.1636 | C9: 0.1077 | D9: 0.1065 | E9: 0.1537 | F9: 0.1309 | G9: 0.1508 | H9: 0.1713 | I9: 0.1214 | J9: 0.1199 | K9: 0.1641 | L9: 0.1798 | M9: 0.2004 | N9: 0.2026 | O9: 0.101 | P9: 0.1303 | Q9: 0.1389 | R9: 0.1151 | S9: 0.1616 | T9: 0.1282 | U9: 0.1149 | V9: 0.1154 | W9: 0.1634 | X9: 0.1482 | Y9: 0.2002 | Z9: 0.192 | AA9: 0.1694 | AB9: 0.152 | AC9: 0.1626 | AD9: 0.1684 | AE9: 0.1799 | AF9: 0.1503 | AG9: 0.1082 | AH9: 0.124 | AI9: 0.1626 | AJ9: 0.1545 | AK9: 0.1711 | AL9: 0.2099 | AM9: 0.1465 | AN9: 0.1737 | AO9: 0.1652 | AP9: 0.1689 | AQ9: 0.1463 | AR9: 0.1252 | AS9: 0.0948 | AT9: 0.1141 | AU9: 0.1604 | AV9: 0.147 | AW9: 0.1651 | AX9: 0.1874 | AY9: 0.1721 | AZ9: 0.1435
A10: 新增注册角色 | B10: 3192473 | C10: 2519319 | D10: 1739098 | E10: 1779321 | F10: 1530699 | G10: 1672478 | H10: 2774404 | I10: 3142565 | J10: 1957442 | K10: 1887215 | L10: 1016575 | M10: 1552450 | N10: 5002855 | O10: 3492692 | P10: 3231128 | Q10: 4369968 | R10: 3111683 | S10: 3581861 | T10: 4863476 | U10: 5119148 | V10: 2811126 | W10: 3126329 | X10: 2206898 | Y10: 2672310 | Z10: 3234314 | AA10: 4344818 | AB10: 3393467 | AC10: 3094448 | AD10: 3156133 | AE10: 4618774 | AF10: 7112200 | AG10: 5657495 | AH10: 3437761 | AI10: 3695571 | AJ10: 2844144 | AK10: 2396264 | AL10: 3934858 | AM10: 3110718 | AN10: 2820780 | AO10: 2722369 | AP10: 3140861 | AQ10: 5037306 | AR10: 7607893 | AS10: 5862209 | AT10: 3299965 | AU10: 3793363 | AV10: 2967853 | AW10: 2446637 | AX10: 2968260 | AY10: 4332823 | AZ10: 2894494
A11: 新增注册角色增长率 | B11: 0.7808 | C11: -0.2109 | D11: -0.3097 | E11: 0.0231 | F11: -0.1397 | G11: 0.0926 | H11: 0.6589 | I11: 0.1327 | J11: -0.3771 | K11: -0.0359 | L11: -0.4613 | M11: 0.5271 | N11: 0 | O11: -0.3019 | P11: -0.0749 | Q11: 0.3525 | R11: -0.2879 | S11: 0.1511 | T11: 0.3578 | U11: 0.0526 | V11: -0.4509 | W11: 0.1121 | X11: -0.2941 | Y11: 0.2109 | Z11: 0.2103 | AA11: 0.3434 | AB11: -0.219 | AC11: -0.0881 | AD11: 0.0199 | AE11: 0.4634 | AF11: 0.5398 | AG11: -0.2045 | AH11: -0.3924 | AI11: 0.075 | AJ11: -0.2304 | AK11: -0.1575 | AL11: 0.6421 | AM11: -0.2094 | AN11: -0.0932 | AO11: -0.0349 | AP11: 0.1537 | AQ11: 0.6038 | AR11: 0.5103 | AS11: -0.2295 | AT11: -0.4371 | AU11: 0.1495 | AV11: -0.2176 | AW11: -0.1756 | AX11: 0.2132 | AY11: 0.4597 | AZ11: -0.332
A12: 新增活跃用户 | B12: 3155576 | C12: 2488946 | D12: 1689276 | E12: 1710364 | F12: 1473349 | G12: 1516254 | H12: 2329659 | I12: 2588471 | J12: 1775970 | K12: 1770642 | L12: 947781 | M12: 1481695 | N12: 4795627 | O12: 3301068 | P12: 3055786 | Q12: 4135725 | R12: 2973836 | S12: 3397470 | T12: 4618319 | U12: 4689397 | V12: 2662247 | W12: 2971545 | X12: 2080247 | Y12: 2519752 | Z12: 3067810 | AA12: 4111216 | AB12: 3222777 | AC12: 2940423 | AD12: 2912558 | AE12: 4072682 | AF12: 6650218 | AG12: 5278612 | AH12: 3234445 | AI12: 3503160 | AJ12: 2700279 | AK12: 2268308 | AL12: 3750790 | AM12: 2988686 | AN12: 2748117 | AO12: 2640594 | AP12: 3060654 | AQ12: 4955585 | AR12: 7369052 | AS12: 5755969 | AT12: 3243214 | AU12: 3729035 | AV12: 2906373 | AW12: 2402005 | AX12: 2914885 | AY12: 4243154 | AZ12: 2831607
A13: 新增活跃用户增长率 | B13: 0.7927 | C13: -0.2113 | D13: -0.3213 | E13: 0.0125 | F13: -0.1386 | G13: 0.0291 | H13: 0.5365 | I13: 0.1111 | J13: -0.3139 | K13: -0.003 | L13: -0.4647 | M13: 0.5633 | N13: 0 | O13: -0.3117 | P13: -0.0743 | Q13: 0.3534 | R13: -0.2809 | S13: 0.1425 | T13: 0.3593 | U13: 0.0154 | V13: -0.4323 | W13: 0.1162 | X13: -0.2999 | Y13: 0.2113 | Z13: 0.2175 | AA13: 0.3401 | AB13: -0.2161 | AC13: -0.0876 | AD13: -0.0095 | AE13: 0.3983 | AF13: 0.6329 | AG13: -0.2062 | AH13: -0.3873 | AI13: 0.0831 | AJ13: -0.2292 | AK13: -0.16 | AL13: 0.6536 | AM13: -0.2032 | AN13: -0.0805 | AO13: -0.0391 | AP13: 0.1591 | AQ13: 0.6191 | AR13: 0.487 | AS13: -0.2189 | AT13: -0.4365 | AU13: 0.1498 | AV13: -0.2206 | AW13: -0.1735 | AX13: 0.2135 | AY13: 0.4557 | AZ13: -0.3327
A14: 留存用户 | B14: 5776495 | C14: 6326681 | D14: 5536522 | E14: 5289541 | F14: 5115106 | G14: 4930833 | H14: 5045004 | I14: 5243039 | J14: 4540015 | K14: 4365701 | L14: 3823037 | M14: 3404515 | N14: 4001514 | O14: 4799052 | P14: 4136685 | Q14: 4241897 | R14: 4295907 | S14: 4245764 | T14: 4436957 | U14: 4428364 | V14: 3669796 | W14: 3337015 | X14: 2888205 | Y14: 2697631 | Z14: 2987522 | AA14: 3415111 | AB14: 3357664 | AC14: 3254923 | AD14: 3390546 | AE14: 3617997 | AF14: 4592252 | AG14: 5337305 | AH14: 4029299 | AI14: 3717872 | AJ14: 3317431 | AK14: 2723435 | AL14: 2799551 | AM14: 3014921 | AN14: 2532262 | AO14: 2460391 | AP14: 2465288 | AQ14: 2757892 | AR14: 3934538 | AS14: 4215649 | AT14: 2915708 | AU14: 2652519 | AV14: 2433677 | AW14: 2065766 | AX14: 1996875 | AY14: 2212499 | AZ14: 2027795
... A31: ACU增长率 | B31: 0.6998 | C31: -0.0915 | D31: -0.4348 | E31: 0.0775 | F31: -0.0911 | G31: -0.0154 | H31: 0.4782 | I31: -0.0106 | J31: -0.446 | K31: -0.0504 | L31: -0.3045 | M31: 0.0123 | N31: 1.461 | O31: -0.2658 | P31: -0.1575 | Q31: 0.3558 | R31: -0.2399 | S31: 0.3643 | T31: 0.3652 | U31: -0.0875 | V31: -0.5054 | W31: 0.0523 | X31: -0.2848 | Y31: 0.154 | Z31: 0.2846 | AA31: 0.4334 | AB31: -0.3613 | AC31: 0.0342 | AD31: 0.0383 | AE31: 0.3665 | AF31: 0.8299 | AG31: -0.1468 | AH31: -0.5329 | AI31: -0.0293 | AJ31: -0.2121 | AK31: -0.0537 | AL31: 0.5686 | AM31: -0.1732 | AN31: -0.2178 | AO31: -0.0823 | AP31: -0.0017 | AQ31: 0.5603 | AR31: 0.8265 | AS31: -0.3185 | AT31: -0.5614 | AU31: 0.0192 | AV31: -0.0937 | AW31: -0.0976 | AX31: 0.1686 | AY31: 0.4277 | AZ31: -0.3265
A32: 活跃用户日平均在线时长 | N32: 3601.9052 | O32: 3287 | P32: 3201 | Q32: 3540 | R32: 3260 | S32: 3760 | T32: 4122 | U32: 4016 | V32: 3389 | W32: 3457 | X32: 3316 | Y32: 3577 | Z32: 3856 | AA32: 3852 | AB32: 3334 | AC32: 3466 | AD32: 3412 | AE32: 3742 | AF32: 4165 | AG32: 3936 | AH32: 3164 | AI32: 3199 | AJ32: 3114 | AK32: 3342 | AL32: 3751 | AM32: 3630 | AN32: 3330 | AO32: 3170 | AP32: 3148 | AQ32: 3192 | AR32: 3560 | AS32: 3270 | AT32: 2676 | AU32: 2691 | AV32: 2794 | AW32: 2900 | AX32: 3059 | AY32: 3116 | AZ32: 2893
A33: 新增用户日平均在线时长 | N33: 3528.0833 | O33: 3189 | P33: 2997 | Q33: 3247 | R33: 3066 | S33: 3645 | T33: 4094 | U33: 3947 | V33: 3056 | W33: 3211 | X33: 3162 | Y33: 3550 | Z33: 3871 | AA33: 3950 | AB33: 3412 | AC33: 3507 | AD33: 3413 | AE33: 3885 | AF33: 4160 | AG33: 3697 | AH33: 3052 | AI33: 3075 | AJ33: 3111 | AK33: 3172 | AL33: 3520 | AM33: 3408 | AN33: 3128 | AO33: 2945 | AP33: 2959 | AQ33: 3103 | AR33: 3394 | AS33: 3055 | AT33: 2580 | AU33: 2534 | AV33: 2639 | AW33: 2619 | AX33: 2768 | AY33: 2839 | AZ33: 2711
A34: 留存用户日平均在线时长 | N34: 3738.165 | O34: 3348 | P34: 3328 | Q34: 3719 | R34: 3367 | S34: 3889 | T34: 4207 | U34: 4104 | V34: 3550 | W34: 3650 | X34: 3453 | Y34: 3717 | Z34: 4001 | AA34: 3922 | AB34: 3387 | AC34: 3555 | AD34: 3500 | AE34: 3778 | AF34: 4259 | AG34: 4069 | AH34: 3257 | AI34: 3352 | AJ34: 3206 | AK34: 3511 | AL34: 4041 | AM34: 3827 | AN34: 3534 | AO34: 3381 | AP34: 3371 | AQ34: 3371 | AR34: 3742 | AS34: 3455 | AT34: 2783 | AU34: 2911 | AV34: 2986 | AW34: 3160 | AX34: 3398 | AY34: 3487 | AZ34: 3141
A35: 回流用户日平均在线时长 | N35: 3100.2212 | O35: 2807 | P35: 2514 | Q35: 2749 | R35: 2445 | S35: 3017 | T35: 3511 | U35: 3408 | V35: 2718 | W35: 2707 | X35: 2590 | Y35: 2877 | Z35: 3161 | AA35: 3272 | AB35: 2798 | AC35: 2820 | AD35: 2755 | AE35: 3246 | AF35: 3625 | AG35: 3250 | AH35: 2584 | AI35: 2394 | AJ35: 2365 | AK35: 2505 | AL35: 2987 | AM35: 2865 | AN35: 2622 | AO35: 2407 | AP35: 2419 | AQ35: 2774 | AR35: 3328 | AS35: 2877 | AT35: 2249 | AU35: 2116 | AV35: 2169 | AW35: 2219 | AX35: 2367 | AY35: 2481 | AZ35: 2223
A36: 活跃用户月平均登录天数 | N36: 4.43 | O36: 4.13 | P36: 4.17 | Q36: 4.07 | R36: 4.21 | S36: 4.3 | T36: 4.66 | U36: 4.24 | V36: 3.62 | W36: 3.59 | X36: 3.36 | Y36: 3.33 | Z36: 3.48 | AA36: 3.72 | AB36: 3.6 | AC36: 3.63 | AD36: 3.86 | AE36: 3.78 | AF36: 4.56 | AG36: 4.62 | AH36: 3.72 | AI36: 3.54 | AJ36: 3.36 | AK36: 3.6 | AL36: 3.65 | AM36: 3.31 | AN36: 3.46 | AO36: 3.37 | AP36: 3.23 | AQ36: 3.55 | AR36: 4.17 | AS36: 3.67 | AT36: 3 | AU36: 2.87 | AV36: 2.96 | AW36: 3.1 | AX36: 3.04 | AY36: 2.99 | AZ36: 3.11
A37: 新增用户月平均登录天数 | N37: 2.16 | O37: 2.09 | P37: 2.09 | Q37: 2.09 | R37: 2.13 | S37: 2.21 | T37: 2.52 | U37: 2.34 | V37: 2.04 | W37: 2.12 | X37: 2.05 | Y37: 2.12 | Z37: 2.18 | AA37: 2.22 | AB37: 2.22 | AC37: 2.15 | AD37: 2.26 | AE37: 2.33 | AF37: 2.84 | AG37: 2.5 | AH37: 2.1 | AI37: 2.13 | AJ37: 2.07 | AK37: 2.13 | AL37: 2.2 | AM37: 2.02 | AN37: 2.14 | AO37: 2 | AP37: 2 | AQ37: 2.81 | AR37: 3 | AS37: 2.55 | AT37: 2.19 | AU37: 2.13 | AV37: 2.13 | AW37: 2.07 | AX37: 2.08 | AY37: 2.11 | AZ37: 2.3
A38: 留存用户月平均登录天数 | N38: 7.88 | O38: 5.85 | P38: 6.16 | Q38: 6.54 | R38: 6.1 | S38: 6.61 | T38: 7.42 | U38: 6.71 | V38: 5.08 | W38: 5.45 | X38: 4.73 | Y38: 5.07 | Z38: 5.38 | AA38: 6.09 | AB38: 5.37 | AC38: 5.51 | AD38: 5.86 | AE38: 5.97 | AF38: 7.7 | AG38: 7.24 | AH38: 5.43 | AI38: 5.48 | AJ38: 4.91 | AK38: 5.45 | AL38: 6.4 | AM38: 5.04 | AN38: 5.46 | AO38: 5.37 | AP38: 5.26 | AQ38: 5.43 | AR38: 6.82 | AS38: 5.52 | AT38: 4.14 | AU38: 4.34 | AV38: 4.34 | AW38: 4.78 | AX38: 5.01 | AY38: 5.19 | AZ38: 4.64
A39: 回流用户月平均登录天数 | N39: 3.12 | O39: 2.47 | P39: 2.38 | Q39: 2.41 | R39: 2.2 | S39: 2.45 | T39: 2.86 | U39: 2.52 | V39: 2.24 | W39: 2.09 | X39: 1.94 | Y39: 2.1 | Z39: 2.28 | AA39: 2.43 | AB39: 2.32 | AC39: 2.11 | AD39: 2.22 | AE39: 2.59 | AF39: 3.07 | AG39: 2.49 | AH39: 2.11 | AI39: 1.91 | AJ39: 1.87 | AK39: 1.94 | AL39: 2.32 | AM39: 1.96 | AN39: 2.19 | AO39: 2.08 | AP39: 2.13 | AQ39: 2.37 | AR39: 3.04 | AS39: 2.32 | AT39: 2.18 | AU39: 1.96 | AV39: 1.96 | AW39: 1.98 | AX39: 2.03 | AY39: 2.16 | AZ39: 2.12
A41: 总体支付情况 | B41: 201101 | C41: 201102 | D41: 201103 | E41: 201104 | F41: 201105 | G41: 201106 | H41: 201107 | I41: 201108 | J41: 201109 | K41: 201110 | L41: 201111 | M41: 201112 | N41: 201201 | O41: 201202 | P41: 201203 | Q41: 201204 | R41: 201205 | S41: 201206 | T41: 201207 | U41: 201208 | V41: 201209 | W41: 201210 | X41: 201211 | Y41: 201212 | Z41: 201301 | AA41: 201302 | AB41: 201303 | AC41: 201304 | AD41: 201305 | AE41: 201306 | AF41: 201307 | AG41: 201308 | AH41: 201309 | AI41: 201310 | AJ41: 201311 | AK41: 201312 | AL41: 201401 | AM41: 201402 | AN41: 201403 | AO41: 201404 | AP41: 201405 | AQ41: 201406 | AR41: 201407 | AS41: 201408 | AT41: 201409 | AU41: 201410 | AV41: 201411 | AW41: 201412 | AX41: 201501 | AY41: 201502 | AZ41: 201503
A42: 付费总额 | B42: 32123599 | C42: 36894506 | D42: 23967439 | E42: 25757499 | F42: 21695812 | G42: 19546261 | H42: 18555169 | I42: 18883212 | J42: 12327202 | K42: 11273181 | L42: 9352357.6 | M42: 10672723 | N42: 15107847 | O42: 17229893 | P42: 12579458 | Q42: 12110076 | R42: 13887055 | S42: 15231927 | T42: 13945913 | U42: 10252351 | V42: 7147410.5 | W42: 6010753 | X42: 6607620.3 | Y42: 7330241.2 | Z42: 7951642.9 | AA42: 14174713 | AB42: 12715791 | AC42: 10381787 | AD42: 11472833 | AE42: 13837517 | AF42: 17639904 | AG42: 18855919 | AH42: 13175383 | AI42: 11418264 | AJ42: 9723287 | AK42: 9048428.8 | AL42: 12083997 | AM42: 13695893 | AN42: 9289421 | AO42: 7855976.6 | AP42: 8733128.7 | AQ42: 10963147 | AR42: 14526363 | AS42: 11163794 | AT42: 8917664.1 | AU42: 8006488.3 | AV42: 7076763.9 | AW42: 7449044.6 | AX42: 8069678.1 | AY42: 10724108 | AZ42: 9691534
A43: 付费总额增长率 | B43: 0.4322 | C43: 0.1485 | D43: -0.3504 | E43: 0.0747 | F43: -0.1577 | G43: -0.0991 | H43: -0.0507 | I43: 0.0177 | J43: -0.3472 | K43: -0.0855 | L43: -0.1704 | M43: 0.1412 | N43: 0 | O43: 0.1405 | P43: -0.2699 | Q43: -0.0373 | R43: 0.1467 | S43: 0.0968 | T43: -0.0844 | U43: -0.2648 | V43: -0.3029 | W43: -0.159 | X43: 0.0993 | Y43: 0.1094 | Z43: 0.0848 | AA43: 0.7826 | AB43: -0.1029 | AC43: -0.1836 | AD43: 0.1051 | AE43: 0.2061 | AF43: 0.2748 | AG43: 0.0689 | AH43: -0.3013 | AI43: -0.1334 | AJ43: -0.1484 | AK43: -0.0694 | AL43: 0.3355 | AM43: 0.1334 | AN43: -0.3217 | AO43: -0.1543 | AP43: 0.1117 | AQ43: 0.2554 | AR43: 0.325 | AS43: -0.2315 | AT43: -0.2012 | AU43: -0.1022 | AV43: -0.1161 | AW43: 0.0526 | AX43: 0.0833 | AY43: 0.3289 | AZ43: -0.0963
A44: 付费用户数 | B44: 951556 | C44: 930502 | D44: 715065 | E44: 672335 | F44: 609372 | G44: 555646 | H44: 555608 | I44: 525022 | J44: 407203 | K44: 402263 | L44: 331276 | M44: 377444 | N44: 468933 | O44: 450339 | P44: 430161 | Q44: 426599 | R44: 409281 | S44: 458968 | T44: 424785 | U44: 306266 | V44: 240381 | W44: 230387 | X44: 201997 | Y44: 216266 | Z44: 276391 | AA44: 345462 | AB44: 310129 | AC44: 268003 | AD44: 288628 | AE44: 333925 | AF44: 442268 | AG44: 404959 | AH44: 333829 | AI44: 309436 | AJ44: 256210 | AK44: 251817 | AL44: 304621 | AM44: 267265 | AN44: 231139 | AO44: 212478 | AP44: 199994 | AQ44: 234415 | AR44: 307104 | AS44: 210059 | AT44: 165359 | AU44: 149868 | AV44: 139102 | AW44: 146569 | AX44: 143817 | AY44: 162018 | AZ44: 162360
A45: 付费用户增长率 | B45: 0.295 | C45: -0.0221 | D45: -0.2315 | E45: -0.0598 | F45: -0.0936 | G45: -0.0882 | H45: -0.0001 | I45: -0.055 | J45: -0.2244 | K45: -0.0121 | L45: -0.1765 | M45: 0.1394 | N45: 0 | O45: -0.0397 | P45: -0.0448 | Q45: -0.0083 | R45: -0.0406 | S45: 0.1214 | T45: -0.0745 | U45: -0.279 | V45: -0.2151 | W45: -0.0416 | X45: -0.1232 | Y45: 0.0706 | Z45: 0.278 | AA45: 0.2499 | AB45: -0.1023 | AC45: -0.1358 | AD45: 0.077 | AE45: 0.1569 | AF45: 0.3245 | AG45: -0.0844 | AH45: -0.1756 | AI45: -0.0731 | AJ45: -0.172 | AK45: -0.0171 | AL45: 0.2097 | AM45: -0.1226 | AN45: -0.1352 | AO45: -0.0807 | AP45: -0.0588 | AQ45: 0.1721 | AR45: 0.3101 | AS45: -0.316 | AT45: -0.2128 | AU45: -0.0937 | AV45: -0.0718 | AW45: 0.0537 | AX45: -0.0188 | AY45: 0.1266 | AZ45: 0.0021
A46: 纯新增付费用户数 | B46: 43067 | C46: 36829 | D46: 27252 | E46: 23442 | F46: 20277 | G46: 19694 | H46: 28788 | I46: 24346 | J46: 15667 | K46: 14916 | L46: 8230 | M46: 12811 | N46: 31307 | O46: 27961 | P46: 24032 | Q46: 27957 | R46: 21667 | S46: 31815 | T46: 33939 | U46: 19633 | V46: 12417 | W46: 13524 | X46: 10564 | Y46: 14320 | Z46: 19716 | AA46: 30180 | AB46: 25505 | AC46: 19300 | AD46: 22278 | AE46: 35265 | AF46: 58167 | AG46: 33024 | AH46: 21092 | AI46: 22137 | AJ46: 19689 | AK46: 17843 | AL46: 26441 | AM46: 20155 | AN46: 20243 | AO46: 16045 | AP46: 18813 | AQ46: 43367 | AR46: 54035 | AS46: 24234 | AT46: 16921 | AU46: 16812 | AV46: 14916 | AW46: 12328 | AX46: 14817 | AY46: 19290 | AZ46: 20987
A47: 历史转化新增付费用户数 | B47: 162095 | C47: 168689 | D47: 110646 | E47: 94132 | F47: 76878 | G47: 70649 | H47: 75385 | I47: 70196 | J47: 54682 | K47: 53808 | L47: 40788 | M47: 42231 | N47: 62548 | O47: 67805 | P47: 60603 | Q47: 61088 | R47: 56116 | S47: 65587 | T47: 62951 | U47: 39028 | V47: 31229 | W47: 29811 | X47: 24707 | Y47: 27135 | Z47: 42244 | AA47: 62650 | AB47: 58129 | AC47: 47882 | AD47: 52285 | AE47: 60850 | AF47: 87222 | AG47: 88886 | AH47: 73813 | AI47: 65750 | AJ47: 41795 | AK47: 40412 | AL47: 56339 | AM47: 47201 | AN47: 38528 | AO47: 35646 | AP47: 27128 | AQ47: 31989 | AR47: 55051 | AS47: 33682 | AT47: 26381 | AU47: 21233 | AV47: 20231 | AW47: 25669 | AX47: 21400 | AY47: 24493 | AZ47: 27668
A48: 活跃付费用户数 | B48: 423016 | C48: 453254 | D48: 391050 | E48: 348444 | F48: 331969 | G48: 293660 | H48: 252102 | I48: 252519 | J48: 208774 | K48: 197632 | L48: 181502 | M48: 179282 | N48: 192581 | O48: 206961 | P48: 217899 | Q48: 217064 | R48: 213491 | S48: 215028 | T48: 203066 | U48: 164179 | V48: 126077 | W48: 119387 | X48: 113396 | Y48: 111737 | Z48: 114769 | AA48: 118261 | AB48: 131720 | AC48: 127341 | AD48: 127041 | AE48: 130822 | AF48: 150875 | AG48: 173104 | AH48: 156273 | AI48: 148962 | AJ48: 130010 | AK48: 123540 | AL48: 124301 | AM48: 124720 | AN48: 109865 | AO48: 102686 | AP48: 97580 | AQ48: 87745 | AR48: 100503 | AS48: 92441 | AT48: 75096 | AU48: 71973 | AV48: 67964 | AW48: 68554 | AX48: 64837 | AY48: 63745 | AZ48: 67412
A49: 回流付费用户数 | B49: 323379 | C49: 271730 | D49: 186117 | E49: 206317 | F49: 180248 | G49: 171643 | H49: 199333 | I49: 177961 | J49: 128080 | K49: 135907 | L49: 100756 | M49: 143120 | N49: 183819 | O49: 147089 | P49: 127221 | Q49: 120127 | R49: 117584 | S49: 146223 | T49: 124598 | U49: 83285 | V49: 70563 | W49: 67591 | X49: 53260 | Y49: 63001 | Z49: 99551 | AA49: 134235 | AB49: 94666 | AC49: 73388 | AD49: 86918 | AE49: 106708 | AF49: 145686 | AG49: 109765 | AH49: 82489 | AI49: 72482 | AJ49: 60093 | AK49: 66634 | AL49: 93066 | AM49: 71892 | AN49: 59935 | AO49: 55994 | AP49: 54852 | AQ49: 69465 | AR49: 95015 | AS49: 58380 | AT49: 46020 | AU49: 39148 | AV49: 35389 | AW49: 39311 | AX49: 42135 | AY49: 53734 | AZ49: 45568
A50: 纯新增付费用户占比 | B50: 0.0453 | C50: 0.0396 | D50: 0.0381 | E50: 0.0349 | F50: 0.0333 | G50: 0.0354 | H50: 0.0518 | I50: 0.0464 | J50: 0.0385 | K50: 0.0371 | L50: 0.0248 | M50: 0.0339 | N50: 0.0668 | O50: 0.0621 | P50: 0.0559 | Q50: 0.0655 | R50: 0.0529 | S50: 0.0693 | T50: 0.0799 | U50: 0.0641 | V50: 0.0517 | W50: 0.0587 | X50: 0.0523 | Y50: 0.0662 | Z50: 0.0713 | AA50: 0.0874 | AB50: 0.0822 | AC50: 0.072 | AD50: 0.0772 | AE50: 0.1056 | AF50: 0.1315 | AG50: 0.0815 | AH50: 0.0632 | AI50: 0.0715 | AJ50: 0.0768 | AK50: 0.0709 | AL50: 0.0868 | AM50: 0.0754 | AN50: 0.0876 | AO50: 0.0755 | AP50: 0.0941 | AQ50: 0.185 | AR50: 0.176 | AS50: 0.1154 | AT50: 0.1023 | AU50: 0.1122 | AV50: 0.1072 | AW50: 0.0841 | AX50: 0.103 | AY50: 0.1191 | AZ50: 0.1293
A51: 历史转化新增付费用户占比 | B51: 0.1703 | C51: 0.1813 | D51: 0.1547 | E51: 0.14 | F51: 0.1262 | G51: 0.1271 | H51: 0.1357 | I51: 0.1337 | J51: 0.1343 | K51: 0.1338 | L51: 0.1231 | M51: 0.1119 | N51: 0.1334 | O51: 0.1506 | P51: 0.1409 | Q51: 0.1432 | R51: 0.1371 | S51: 0.1429 | T51: 0.1482 | U51: 0.1274 | V51: 0.1299 | W51: 0.1294 | X51: 0.1223 | Y51: 0.1255 | Z51: 0.1528 | AA51: 0.1814 | AB51: 0.1874 | AC51: 0.1787 | AD51: 0.1812 | AE51: 0.1822 | AF51: 0.1972 | AG51: 0.2195 | AH51: 0.2211 | AI51: 0.2125 | AJ51: 0.1631 | AK51: 0.1605 | AL51: 0.1849 | AM51: 0.1766 | AN51: 0.1667 | AO51: 0.1678 | AP51: 0.1356 | AQ51: 0.1365 | AR51: 0.1793 | AS51: 0.1603 | AT51: 0.1595 | AU51: 0.1417 | AV51: 0.1454 | AW51: 0.1751 | AX51: 0.1488 | AY51: 0.1512 | AZ51: 0.1704
A52: 活跃付费用户占比 | B52: 0.4446 | C52: 0.4871 | D52: 0.5469 | E52: 0.5183 | F52: 0.5448 | G52: 0.5285 | H52: 0.4537 | I52: 0.481 | J52: 0.5127 | K52: 0.4913 | L52: 0.5479 | M52: 0.475 | N52: 0.4107 | O52: 0.4596 | P52: 0.5066 | Q52: 0.5088 | R52: 0.5216 | S52: 0.4685 | T52: 0.478 | U52: 0.5361 | V52: 0.5245 | W52: 0.5182 | X52: 0.5614 | Y52: 0.5167 | Z52: 0.4152 | AA52: 0.3423 | AB52: 0.4247 | AC52: 0.4751 | AD52: 0.4402 | AE52: 0.3918 | AF52: 0.3411 | AG52: 0.4275 | AH52: 0.4681 | AI52: 0.4814 | AJ52: 0.5074 | AK52: 0.4906 | AL52: 0.4081 | AM52: 0.4667 | AN52: 0.4753 | AO52: 0.4833 | AP52: 0.4879 | AQ52: 0.3743 | AR52: 0.3273 | AS52: 0.4401 | AT52: 0.4541 | AU52: 0.4802 | AV52: 0.4886 | AW52: 0.4677 | AX52: 0.4508 | AY52: 0.3934 | AZ52: 0.4152
... A71: 按条支付arppu值增长率 | B71: 0.1986 | C71: 0.1544 | D71: -0.1476 | E71: 0.256 | F71: -0.2042 | G71: 0.0455 | H71: 0.0352 | I71: 0.0685 | J71: -0.1942 | K71: 0.0051 | L71: -0.0034 | M71: -0.1177 | N71: 0 | O71: 0.2427 | P71: -0.1849 | Q71: -0.0822 | R71: 0.1439 | S71: 0.0571 | T71: -0.0266 | U71: 0.1157 | V71: -0.1119 | W71: -0.1123 | X71: 0.3148 | Y71: 0.1328 | Z71: -0.3241 | AA71: 0.2318 | AB71: 0.0977 | AC71: 0.0356 | AD71: 0.0022 | AE71: 0.0147 | AF71: -0.0629 | AG71: 0.1455 | AH71: -0.2192 | AI71: 0.0088 | AJ71: 0.0988 | AK71: -0.0416 | AL71: 0 | AM71: 0.1698 | AN71: -0.0873 | AO71: -0.028 | AP71: 0.3592 | AQ71: 0.0896 | AR71: -0.0624 | AS71: 0.1811 | AT71: 0.0775 | AU71: 0.0381 | AV71: -0.1072 | AW71: -0.2056 | AX71: 0.1869 | AY71: 0.2215 | AZ71: -0.1024
A74: 约瑟传说
A75: 活跃在线情况 | B75: 201101 | C75: 201102 | D75: 201103 | E75: 201104 | F75: 201105 | G75: 201106 | H75: 201107 | I75: 201108 | J75: 201109 | K75: 201110 | L75: 201111 | M75: 201112 | N75: 201201 | O75: 201202 | P75: 201203 | Q75: 201204 | R75: 201205 | S75: 201206 | T75: 201207 | U75: 201208 | V75: 201209 | W75: 201210 | X75: 201211 | Y75: 201212 | Z75: 201301 | AA75: 201302 | AB75: 201303 | AC75: 201304 | AD75: 201305 | AE75: 201306 | AF75: 201307 | AG75: 201308 | AH75: 201309 | AI75: 201310 | AJ75: 201311 | AK75: 201312 | AL75: 201401 | AM75: 201402 | AN75: 201403 | AO75: 201404 | AP75: 201405 | AQ75: 201406 | AR75: 201407 | AS75: 201408 | AT75: 201409 | AU75: 201410 | AV75: 201411 | AW75: 201412 | AX75: 201501 | AY75: 201502 | AZ75: 201503
A76: 活跃用户 | B76: 0 | C76: 0 | D76: 0 | E76: 0 | F76: 0 | G76: 0 | H76: 4243041 | I76: 4605577 | J76: 2423211 | K76: 2534908 | L76: 1794138 | M76: 1665484 | N76: 3006820 | O76: 2541497 | P76: 2348413 | Q76: 3535012 | R76: 3115068 | S76: 3374948 | T76: 3895428 | U76: 4008431 | V76: 2435229 | W76: 2444548 | X76: 1730399 | Y76: 1897657 | Z76: 2947368 | AA76: 3079738 | AB76: 2308778 | AC76: 2268731 | AD76: 2089460 | AE76: 2387729 | AF76: 3979432 | AG76: 3531009 | AH76: 2056121 | AI76: 2132995 | AJ76: 1664045 | AK76: 1336817 | AL76: 2061577 | AM76: 2060237 | AN76: 1936115 | AO76: 1932187 | AP76: 2155426 | AQ76: 2507040 | AR76: 3475928 | AS76: 3150670 | AT76: 1529678 | AU76: 1858434 | AV76: 1652894 | AW76: 1394709 | AX76: 1589817 | AY76: 2132994 | AZ76: 1426820
A77: 活跃用户增长率 | B77: 0 | C77: 0 | D77: 0 | E77: 0 | F77: 0 | G77: 0 | H77: 0 | I77: 0.0854 | J77: -0.4739 | K77: 0.0461 | L77: -0.2922 | M77: -0.0717 | N77: =N76/M76-1 -> 0.80537309 | O77: -0.1548 | P77: -0.076 | Q77: 0.5053 | R77: -0.1188 | S77: 0.0834 | T77: 0.1542 | U77: 0.029 | V77: -0.3925 | W77: 0.0038 | X77: -0.2921 | Y77: 0.0967 | Z77: 0.5532 | AA77: 0.0449 | AB77: -0.2503 | AC77: -0.0173 | AD77: -0.079 | AE77: 0.1427 | AF77: 0.6666 | AG77: -0.1127 | AH77: -0.4177 | AI77: 0.0374 | AJ77: -0.2199 | AK77: -0.1966 | AL77: 0.5422 | AM77: -0.0006 | AN77: -0.0602 | AO77: -0.002 | AP77: 0.1155 | AQ77: 0.1631 | AR77: 0.3865 | AS77: -0.0936 | AT77: -0.5145 | AU77: 0.2149 | AV77: -0.1106 | AW77: -0.1562 | AX77: 0.1399 | AY77: 0.3417 | AZ77: -0.3311
...

Sheet 历史新
A1: 赛尔号付费情况 | C1: 2011-01 | D1: 2011-02 | E1: 2011-03 | F1: 2011-04 | G1: 2011-05 | H1: 2011-06 | I1: 2011-07 | J1: 2011-08 | K1: 2011-09 | L1: 2011-10 | M1: 2011-11 | N1: 2011-12 | O1: 2012-01 | P1: 2012-02 | Q1: 2012-03 | R1: 2012-04 | S1: 2012-05 | T1: 2012-06 | U1: 2012-07 | V1: 2012-08 | W1: 2012-09 | X1: 2012-10 | Y1: 2012-11 | Z1: 2012-12 | AA1: 2013-01 | AB1: 2013-02 | AC1: 2013-03 | AD1: 2013-04 | AE1: 2013-05 | AF1: 2013-06 | AG1: 2013-07 | AH1: 2013-08 | AI1: 2013-09 | AJ1: 2013-10 | AK1: 2013-11 | AL1: 2013-12 | AM1: 2014-01 | AN1: 2014-02 | AO1: 2014-03 | AP1: 2014-04 | AQ1: 2014-05 | AR1: 2014-06 | AS1: 2014-07 | AT1: 2014-08 | AU1: 2014-09 | AV1: 2014-10 | AW1: 2014-11 | AX1: 2014-12 | AY1: 2015-01 | AZ1: 2015-02 | BA1: 2015-03 | BB1: 2015-04 | BC1: 2015-05 | BD1: 2015-06 | BE1: 42186 | BF1: 42217 | BG1: 42248 | BH1: 42278 | BI1: 42309 | BJ1: 42339 | BK1: 42370 | BL1: 42401 | BM1: 42430 | BN1: 42461 | BO1: 42491 | BP1: 42522 | BQ1: 42552 | BR1: 42583
A2: 基本情况 | B2: 付费总额(元) | C2: 32214859 | D2: 36949986 | E2: 24005069 | F2: 25795219 | G2: 21735492 | H2: 19577851 | I2: 18607239 | J2: 18931392 | K2: 12353432 | L2: 11307711 | M2: 9372817.6 | N2: 10696623 | O2: 15156367 | P2: 17263013 | Q2: 12623948 | R2: 12140136 | S2: 13911665 | T2: 15265537 | U2: 13980393 | V2: 10276391 | W2: 7163760.5 | X2: 6029393 | Y2: 6621080.3 | Z2: 7351451.2 | AA2: 7984752.9 | AB2: 14206733 | AC2: 12739961 | AD2: 10407097 | AE2: 11495323 | AF2: 13880407 | AG2: 17709614 | AH2: 18916039 | AI2: 13205883 | AJ2: 11444374 | AK2: 9746767 | AL2: 9059788.8 | AM2: 12090917 | AN2: 13703873 | AO2: 9294771 | AP2: 7861986.6 | AQ2: 8734578.7 | AR2: 10963177 | AS2: 14529713 | AT2: 11165684 | AU2: 8918814.1 | AV2: 8007658.3 | AW2: 7077513.9 | AX2: 7449654.6 | AY2: 8070608.1 | AZ2: 10725468 | BA2: 9692354 | BB2: 8902157 | BC2: 9133285.9 | BD2: 9508313.7 | BE2: 11068460 | BF2: 11295530 | BG2: 8613110.1 | BH2: 7274075.9 | BI2: 5861264.1 | BJ2: 5416807.5 | BK2: 7145626.2 | BL2: 11250348 | BM2: 6492509.4 | BN2: 7859361 | BO2: 7016380.1 | BP2: 8398391.5 | BQ2: 8183185.7 | BR2: 7342280.3
B3: 付费总额(元)增长率 | C3: 0.4329 | D3: 0.147 | E3: -0.3503 | F3: 0.0746 | G3: -0.1574 | H3: -0.0993 | I3: -0.0496 | J3: 0.0174 | K3: -0.3475 | L3: -0.0847 | M3: -0.1711 | N3: 0.1412 | O3: 0.4169 | P3: 0.139 | Q3: -0.2687 | R3: -0.0383 | S3: 0.1459 | T3: 0.0973 | U3: -0.0842 | V3: -0.2649 | W3: -0.3029 | X3: -0.1583 | Y3: 0.0981 | Z3: 0.1103 | AA3: 0.0861 | AB3: 0.7792 | AC3: -0.1032 | AD3: -0.1831 | AE3: 0.1046 | AF3: 0.2075 | AG3: 0.2759 | AH3: 0.0681 | AI3: -0.3019 | AJ3: -0.1334 | AK3: -0.1483 | AL3: -0.0705 | AM3: 0.3346 | AN3: 0.1334 | AO3: -0.3217 | AP3: -0.1541 | AQ3: 0.111 | AR3: 0.2551 | AS3: 0.3253 | AT3: -0.2315 | AU3: -0.2012 | AV3: -0.1022 | AW3: -0.1162 | AX3: 0.0526 | AY3: 0.0834 | AZ3: 0.329 | BA3: -0.0963 | BB3: -0.0815 | BC3: 0.026 | BD3: 0.0411 | BE3: 0.1641 | BF3: 0.0205 | BG3: -0.2375 | BH3: -0.1555 | BI3: -0.1942 | BJ3: -0.0758 | BK3: 0.3192 | BL3: 0.5744 | BM3: -0.4229 | BN3: 0.2105 | BO3: -0.1073 | BP3: 0.197 | BQ3: -0.0256 | BR3: -0.1028
B4: 付费用户数 | C4: 957284 | D4: 932330 | E4: 716691 | F4: 673953 | G4: 610889 | H4: 556999 | I4: 558064 | J4: 526920 | K4: 408315 | L4: 403490 | M4: 332193 | N4: 378643 | O4: 471363 | P4: 451441 | Q4: 432716 | R4: 427927 | S4: 410245 | T4: 460645 | U4: 426112 | V4: 307253 | W4: 241154 | X4: 231225 | Y4: 202597 | Z4: 217340 | AA4: 278146 | AB4: 346606 | AC4: 311137 | AD4: 269279 | AE4: 289529 | AF4: 335981 | AG4: 445616 | AH4: 407443 | AI4: 335073 | AJ4: 310416 | AK4: 256856 | AL4: 252149 | AM4: 304621 | AN4: 267265 | AO4: 231139 | AP4: 212478 | AQ4: 199994 | AR4: 234415 | AS4: 307103 | AT4: 210058 | AU4: 165359 | AV4: 149868 | AW4: 139102 | AX4: 146569 | AY4: 143817 | AZ4: 162018 | BA4: 162360 | BB4: 146274 | BC4: 147164 | BD4: 156898 | BE4: 181953 | BF4: 179473 | BG4: 123819 | BH4: 122626 | BI4: 85624 | BJ4: 99822 | BK4: 110179 | BL4: 124663 | BM4: 99637 | BN4: 103431 | BO4: 103106 | BP4: 128996 | BQ4: 115664 | BR4: 107797
B5: 付费用户数增长率 | C5: 0.2964 | D5: -0.0261 | E5: -0.2313 | F5: -0.0596 | G5: -0.0936 | H5: -0.0882 | I5: 0.0019 | J5: -0.0558 | K5: -0.2251 | L5: -0.0118 | M5: -0.1767 | N5: 0.1398 | O5: 0.2449 | P5: -0.0423 | Q5: -0.0415 | R5: -0.0111 | S5: -0.0413 | T5: 0.1229 | U5: -0.075 | V5: -0.2789 | W5: -0.2151 | X5: -0.0412 | Y5: -0.1238 | Z5: 0.0728 | AA5: 0.2798 | AB5: 0.2461 | AC5: -0.1023 | AD5: -0.1345 | AE5: 0.0752 | AF5: 0.1604 | AG5: 0.3263 | AH5: -0.0857 | AI5: -0.1776 | AJ5: -0.0736 | AK5: -0.1725 | AL5: -0.0183 | AM5: 0.2081 | AN5: -0.1226 | AO5: -0.1352 | AP5: -0.0807 | AQ5: -0.0588 | AR5: 0.1721 | AS5: 0.3101 | AT5: -0.316 | AU5: -0.2128 | AV5: -0.0937 | AW5: -0.0718 | AX5: 0.0537 | AY5: -0.0188 | AZ5: 0.1266 | BA5: 0.0021 | BB5: -0.0991 | BC5: 0.0061 | BD5: 0.0661 | BE5: 0.1597 | BF5: -0.0136 | BG5: -0.3101 | BH5: -0.0096 | BI5: -0.3017 | BJ5: 0.1658 | BK5: 0.1038 | BL5: 0.1315 | BM5: -0.2007 | BN5: 0.0381 | BO5: -0.0031 | BP5: 0.2511 | BQ5: -0.1034 | BR5: -0.068
B6: arppu值 | C6: 33.65 | D6: 39.63 | E6: 33.49 | F6: 38.27 | G6: 35.58 | H6: 35.15 | I6: 33.34 | J6: 35.93 | K6: 30.25 | L6: 28.02 | M6: 28.21 | N6: 28.25 | O6: 32.15 | P6: 38.24 | Q6: 29.17 | R6: 28.37 | S6: 33.91 | T6: 33.14 | U6: 32.81 | V6: 33.45 | W6: 29.71 | X6: 26.08 | Y6: 32.68 | Z6: 33.82 | AA6: 28.71 | AB6: 40.99 | AC6: 40.95 | AD6: 38.65 | AE6: 39.7 | AF6: 41.31 | AG6: 39.74 | AH6: 46.43 | AI6: 39.41 | AJ6: 36.87 | AK6: 37.95 | AL6: 35.93 | AM6: 39.69 | AN6: 51.27 | AO6: 40.21 | AP6: 37 | AQ6: 43.67 | AR6: 46.77 | AS6: 47.31 | AT6: 53.16 | AU6: 53.94 | AV6: 53.43 | AW6: 50.88 | AX6: 50.83 | AY6: 56.12 | AZ6: 66.2 | BA6: 59.7 | BB6: 60.86 | BC6: 62.06 | BD6: 60.6 | BE6: 60.83 | BF6: 62.94 | BG6: 69.56 | BH6: 59.32 | BI6: 68.45 | BJ6: 54.26 | BK6: 64.85 | BL6: 90.25 | BM6: 65.16 | BN6: 75.99 | BO6: 68.05 | BP6: 65.11 | BQ6: 70.75 | BR6: 68.11
B7: arppu值增长率 | C7: 0.1051 | D7: 0.1777 | E7: -0.1549 | F7: 0.1427 | G7: -0.0703 | H7: -0.0121 | I7: -0.0515 | J7: 0.0777 | K7: -0.1581 | L7: -0.0737 | M7: 0.0068 | N7: 0.0014 | O7: 0.1381 | P7: 0.1894 | Q7: -0.2372 | R7: -0.0274 | S7: 0.1953 | T7: -0.0227 | U7: -0.01 | V7: 0.0195 | W7: -0.1118 | X7: -0.1222 | Y7: 0.2531 | Z7: 0.0349 | AA7: -0.1511 | AB7: 0.4277 | AC7: -0.001 | AD7: -0.0562 | AE7: 0.0272 | AF7: 0.0406 | AG7: -0.038 | AH7: 0.1683 | AI7: -0.1512 | AJ7: -0.0645 | AK7: 0.0293 | AL7: -0.0532 | AM7: 0.1046 | AN7: 0.2918 | AO7: -0.2157 | AP7: -0.0798 | AQ7: 0.1803 | AR7: 0.071 | AS7: 0.0115 | AT7: 0.1237 | AU7: 0.0147 | AV7: -0.0095 | AW7: -0.0477 | AX7: -0.001 | AY7: 0.1041 | AZ7: 0.1796 | BA7: -0.0982 | BB7: 0.0194 | BC7: 0.0197 | BD7: -0.0235 | BE7: 0.0038 | BF7: 0.0347 | BG7: 0.1052 | BH7: -0.1472 | BI7: 0.1539 | BJ7: -0.2073 | BK7: 0.1952 | BL7: 0.3917 | BM7: -0.278 | BN7: 0.1662 | BO7: -0.1045 | BP7: -0.0432 | BQ7: 0.0866 | BR7: -0.0373
A8: 包月 | B8: 包月支付总额(不含短信包月续费) | C8: 0 | D8: 0 | E8: 0 | F8: 0 | G8: 0 | H8: 0 | I8: 0 | J8: 0 | K8: 0 | L8: 0 | M8: 0 | N8: 0 | O8: 0 | P8: 0 | Q8: 0 | R8: 0 | S8: 0 | T8: 0 | U8: 0 | V8: 0 | W8: 0 | X8: 0 | Y8: 0 | Z8: 0 | AA8: 0 | AB8: 0 | AC8: 0 | AD8: 0 | AE8: 0 | AF8: 0 | AG8: 0 | AH8: 0 | AI8: 0 | AJ8: 0 | AK8: 0 | AL8: 0 | AM8: 3051990 | AN8: 4775820 | AO8: 2750860 | AP8: 1833460 | AQ8: 2035390 | AR8: 2023410 | AS8: 3790550 | AT8: 1964010 | AU8: 1835430 | AV8: 1638490 | AW8: 1341600 | AX8: 2048200 | AY8: 2335670 | AZ8: 2103060 | BA8: 1873430 | BB8: 2024280 | BC8: 1629040 | BD8: 1951320 | BE8: 2027310 | BF8: 2264030 | BG8: 1391370 | BH8: 1029380 | BI8: 765070 | BJ8: 1439810 | BK8: 2487620 | BL8: 2240270 | BM8: 1293060 | BN8: 1689380 | BO8: 1496610 | BP8: 1498740 | BQ8: 1495350 | BR8: 1364340
B9: 包月支付总额(不含短信包月续费)增长率 | C9: 0 | D9: 0 | E9: 0 | F9: 0 | G9: 0 | H9: 0 | I9: 0 | J9: 0 | K9: 0 | L9: 0 | M9: 0 | N9: 0 | O9: 0 | P9: 0 | Q9: 0 | R9: 0 | S9: 0 | T9: 0 | U9: 0 | V9: 0 | W9: 0 | X9: 0 | Y9: 0 | Z9: 0 | AA9: 0 | AB9: 0 | AC9: 0 | AD9: 0 | AE9: 0 | AF9: 0 | AG9: 0 | AH9: 0 | AI9: 0 | AJ9: 0 | AK9: 0 | AL9: 0 | AM9: 0 | AN9: 0.5648 | AO9: -0.424 | AP9: -0.3335 | AQ9: 0.1101 | AR9: -0.0059 | AS9: 0.8733 | AT9: -0.4819 | AU9: -0.0655 | AV9: -0.1073 | AW9: -0.1812 | AX9: 0.5267 | AY9: 0.1404 | AZ9: -0.0996 | BA9: -0.1092 | BB9: 0.0805 | BC9: -0.1952 | BD9: 0.1978 | BE9: 0.0389 | BF9: 0.1168 | BG9: -0.3854 | BH9: -0.2602 | BI9: -0.2568 | BJ9: 0.8819 | BK9: 0.7277 | BL9: -0.0994 | BM9: -0.4228 | BN9: 0.3065 | BO9: -0.1141 | BP9: 0.0014 | BQ9: -0.0023 | BR9: -0.0876
B10: 包月支付用户数(不含短信包月续费) | C10: 0 | D10: 0 | E10: 0 | F10: 0 | G10: 0 | H10: 0 | I10: 0 | J10: 0 | K10: 0 | L10: 0 | M10: 0 | N10: 0 | O10: 0 | P10: 0 | Q10: 0 | R10: 0 | S10: 0 | T10: 0 | U10: 0 | V10: 0 | W10: 0 | X10: 0 | Y10: 0 | Z10: 0 | AA10: 0 | AB10: 0 | AC10: 0 | AD10: 0 | AE10: 0 | AF10: 0 | AG10: 0 | AH10: 0 | AI10: 0 | AJ10: 0 | AK10: 0 | AL10: 0 | AM10: 135573 | AN10: 126248 | AO10: 107726 | AP10: 82730 | AQ10: 95746 | AR10: 120997 | AS10: 186137 | AT10: 106710 | AU10: 93291 | AV10: 85766 | AW10: 73176 | AX10: 64140 | AY10: 70795 | AZ10: 70812 | BA10: 68774 | BB10: 71586 | BC10: 68870 | BD10: 73121 | BE10: 87274 | BF10: 94287 | BG10: 47486 | BH10: 40839 | BI10: 29989 | BJ10: 35510 | BK10: 50448 | BL10: 47080 | BM10: 35271 | BN10: 40768 | BO10: 38185 | BP10: 51327 | BQ10: 44849 | BR10: 42062
B11: 包月支付用户数(不含短信包月续费)增长率 | C11: 0 | D11: 0 | E11: 0 | F11: 0 | G11: 0 | H11: 0 | I11: 0 | J11: 0 | K11: 0 | L11: 0 | M11: 0 | N11: 0 | O11: 0 | P11: 0 | Q11: 0 | R11: 0 | S11: 0 | T11: 0 | U11: 0 | V11: 0 | W11: 0 | X11: 0 | Y11: 0 | Z11: 0 | AA11: 0 | AB11: 0 | AC11: 0 | AD11: 0 | AE11: 0 | AF11: 0 | AG11: 0 | AH11: 0 | AI11: 0 | AJ11: 0 | AK11: 0 | AL11: 0 | AM11: 0 | AN11: -0.0688 | AO11: -0.1467 | AP11: -0.232 | AQ11: 0.1573 | AR11: 0.2637 | AS11: 0.5384 | AT11: -0.4267 | AU11: -0.1258 | AV11: -0.0807 | AW11: -0.1468 | AX11: -0.1235 | AY11: 0.1038 | AZ11: 0.0002 | BA11: -0.0288 | BB11: 0.0409 | BC11: -0.0379 | BD11: 0.0617 | BE11: 0.1936 | BF11: 0.0804 | BG11: -0.4964 | BH11: -0.14 | BI11: -0.2657 | BJ11: 0.1841 | BK11: 0.4207 | BL11: -0.0668 | BM11: -0.2508 | BN11: 0.1559 | BO11: -0.0634 | BP11: 0.3442 | BQ11: -0.1262 | BR11: -0.0621
B12: 包月支付arppu值 | C12: 0 | D12: 0 | E12: 0 | F12: 0 | G12: 0 | H12: 0 | I12: 0 | J12: 0 | K12: 0 | L12: 0 | M12: 0 | N12: 0 | O12: 0 | P12: 0 | Q12: 0 | R12: 0 | S12: 0 | T12: 0 | U12: 0 | V12: 0 | W12: 0 | X12: 0 | Y12: 0 | Z12: 0 | AA12: 0 | AB12: 0 | AC12: 0 | AD12: 0 | AE12: 0 | AF12: 0 | AG12: 0 | AH12: 0 | AI12: 0 | AJ12: 0 | AK12: 0 | AL12: 0 | AM12: 22.51 | AN12: 37.83 | AO12: 25.54 | AP12: 22.16 | AQ12: 21.26 | AR12: 16.72 | AS12: 20.36 | AT12: 18.41 | AU12: 19.67 | AV12: 19.1 | AW12: 18.33 | AX12: 31.93 | AY12: 32.99 | AZ12: 29.7 | BA12: 27.24 | BB12: 28.28 | BC12: 23.65 | BD12: 26.69 | BE12: 23.23 | BF12: 24.01 | BG12: 29.3 | BH12: 25.21 | BI12: 25.51 | BJ12: 40.55 | BK12: 49.31 | BL12: 47.58 | BM12: 36.66 | BN12: 41.44 | BO12: 39.19 | BP12: 29.2 | BQ12: 33.34 | BR12: 32.44
B13: 包月支付arppu值增长率 | C13: 0 | D13: 0 | E13: 0 | F13: 0 | G13: 0 | H13: 0 | I13: 0 | J13: 0 | K13: 0 | L13: 0 | M13: 0 | N13: 0 | O13: 0 | P13: 0 | Q13: 0 | R13: 0 | S13: 0 | T13: 0 | U13: 0 | V13: 0 | W13: 0 | X13: 0 | Y13: 0 | Z13: 0 | AA13: 0 | AB13: 0 | AC13: 0 | AD13: 0 | AE13: 0 | AF13: 0 | AG13: 0 | AH13: 0 | AI13: 0 | AJ13: 0 | AK13: 0 | AL13: 0 | AM13: 0 | AN13: 0.6806 | AO13: -0.3249 | AP13: -0.1323 | AQ13: -0.0406 | AR13: -0.2135 | AS13: 0.2177 | AT13: -0.0958 | AU13: 0.0684 | AV13: -0.029 | AW13: -0.0403 | AX13: 0.742 | AY13: 0.0332 | AZ13: -0.0997 | BA13: -0.0828 | BB13: 0.0382 | BC13: -0.1637 | BD13: 0.1285 | BE13: -0.1296 | BF13: 0.0336 | BG13: 0.2203 | BH13: -0.1396 | BI13: 0.0119 | BJ13: 0.5896 | BK13: 0.216 | BL13: -0.0351 | BM13: -0.2295 | BN13: 0.1304 | BO13: -0.0543 | BP13: -0.2549 | BQ13: 0.1418 | BR13: -0.027
A14: 按条 | B14: 按条支付总额 | C14: 17766949 | D14: 22405856 | E14: 13212059 | F14: 18513769 | G14: 12812602 | H14: 11956261 | I14: 11763459 | J14: 11931262 | K14: 6941441.6 | L14: 6617011.3 | M14: 5578247.6 | N14: 6561753.3 | O14: 8884187.3 | P14: 10157363 | Q14: 7190958 | R14: 6592405.9 | S14: 8424365.1 | T14: 10550947 | U14: 8903102.7 | V14: 7210871.3 | W14: 4411230.5 | X14: 3683313 | Y14: 4223180.3 | Z14: 4870491.2 | AA14: 5255412.9 | AB14: 9122983.2 | AC14: 8797610.7 | AD14: 7642726.9 | AE14: 8390992.7 | AF14: 9484066.6 | AG14: 11847464 | AH14: 14133199 | AI14: 8415542.7 | AJ14: 8205714.4 | AK14: 6857337 | AL14: 6221738.8 | AM14: 8623866.8 | AN14: 8524023.1 | AO14: 6129691 | AP14: 5608866.6 | AQ14: 6265888.7 | AR14: 8607507.4 | AS14: 10406683 | AT14: 8969543.7 | AU14: 6849504.1 | AV14: 6133798.3 | AW14: 5494963.9 | AX14: 5163074.6 | AY14: 5493428.1 | AZ14: 8378107.6 | BA14: 7570004 | BB14: 6683807 | BC14: 7306665.9 | BD14: 7374563.7 | BE14: 8856600.1 | BF14: 8856009.7 | BG14: 7054060.1 | BH14: 6082365.9 | BI14: 4938984.1 | BJ14: 3823997.5 | BK14: 4509266.2 | BL14: 8870107.9 | BM14: 5061629.4 | BN14: 6034661 | BO14: 5386670.1 | BP14: 6768781.5 | BQ14: 6559215.7 | BR14: 5851180.3
B15: 按条支付总额增长率 | C15: 0.5171 | D15: 0.2611 | E15: -0.4103 | F15: 0.4013 | G15: -0.3079 | H15: -0.0668 | I15: -0.0161 | J15: 0.0143 | K15: -0.4182 | L15: -0.0467 | M15: -0.157 | N15: 0.1763 | O15: 0.3539 | P15: 0.1433 | Q15: -0.292 | R15: -0.0832 | S15: 0.2779 | T15: 0.2524 | U15: -0.1562 | V15: -0.1901 | W15: -0.3883 | X15: -0.165 | Y15: 0.1466 | Z15: 0.1533 | AA15: 0.079 | AB15: 0.7359 | AC15: -0.0357 | AD15: -0.1313 | AE15: 0.0979 | AF15: 0.1303 | AG15: 0.2492 | AH15: 0.1929 | AI15: -0.4046 | AJ15: -0.0249 | AK15: -0.1643 | AL15: -0.0927 | AM15: 0.3861 | AN15: -0.0116 | AO15: -0.2809 | AP15: -0.085 | AQ15: 0.1171 | AR15: 0.3737 | AS15: 0.209 | AT15: -0.1381 | AU15: -0.2364 | AV15: -0.1045 | AW15: -0.1041 | AX15: -0.0604 | AY15: 0.064 | AZ15: 0.5251 | BA15: -0.0965 | BB15: -0.1171 | BC15: 0.0932 | BD15: 0.0093 | BE15: 0.201 | BF15: -0.0001 | BG15: -0.2035 | BH15: -0.1377 | BI15: -0.188 | BJ15: -0.2258 | BK15: 0.1792 | BL15: 0.9671 | BM15: -0.4294 | BN15: 0.1922 | BO15: -0.1074 | BP15: 0.2566 | BQ15: -0.031 | BR15: -0.1079
