Workbook

Sheet 说明
B4: 修订历史
B5: 序号 | C5: 修订内容 | D5: 修订人 | E5: 修订日期
B6: 1 | C6: 建立初始模板,实现填写明细即出收入总额 | D6: lynn | E6: 2015.09.11
B7: 2
B8: 3

Sheet 数据—淘米方
A1: 统一配置项
A2: VIP的套餐单价
A3: 31 | B3: 150
A4: 93 | B4: 450
A5: 186 | B5: 800
A6: 372 | B6: 1500
C8: VIP天数
C9: 请逐月填写
C11: 摩尔庄园 | D11: 包月天数 | E11: 42156 | F11: 42186 | G11: 42217 | H11: 42248 | I11: 42278 | J11: 42309
C12: VIP | D12: 31 | F12: 1407 | G12: 1182 | H12: 715 | I12: 613 | J12: 511
D13: 93 | F13: 40 | G13: 41 | H13: 44 | I13: 32 | J13: 23
D14: 186 | F14: 11 | G14: 18 | H14: 20 | I14: 10 | J14: 5
D15: 372 | F15: 11 | G15: 9 | H15: 9 | I15: 7 | J15: 20
C18: 赛尔号
C19: VIP | D19: 包月天数 | E19: =E11 -> 42156 | F19: =F11 -> 42186 | G19: =G11 -> 42217 | H19: =H11 -> 42248 | I19: 42278 | J19: =J11 -> 42309
D20: 31 | F20: 706 | G20: 1129 | H20: 650 | I20: 597 | J20: 614
D21: 93 | F21: 130 | G21: 97 | H21: 56 | I21: 54 | J21: 39
D22: 186 | F22: 36 | G22: 40 | H22: 57 | I22: 31 | J22: 19
D23: 372 | F23: 46 | G23: 59 | H23: 58 | I23: 43 | J23: 41
C27: 小花仙 | D27: 包月天数 | E27: =E11 -> 42156 | F27: 42186 | G27: 42217 | H27: 42248 | I27: 42278 | J27: 42309
C28: VIP | D28: 31 | F28: 380 | G28: 560 | H28: 346 | I28: 360 | J28: 436
D29: 93 | F29: 229 | G29: 82 | H29: 28 | I29: 170 | J29: 150
D30: 186 | F30: 9 | G30: 14 | H30: 6 | I30: 9 | J30: 7
D31: 372 | F31: 18 | G31: 63 | H31: 31 | I31: 20 | J31: 15
C34: 功夫派
C35: VIP | D35: 包月天数 | E35: =E11 -> 42156 | F35: 42186 | G35: 42217 | H35: 42248 | I35: 42278 | J35: 42309
D36: 31 | F36: 145 | G36: 113 | H36: 79 | I36: 65 | J36: 63
D37: 93 | F37: 9 | G37: 5 | H37: 7 | I37: 10 | J37: 11
D38: 186 | F38: 7 | G38: 2 | H38: 2 | I38: 1 | J38: 2
D39: 372 | F39: 11 | G39: 10 | H39: 3 | I39: 0 | J39: 8
C42: 热血精灵派
C43: VIP | D43: 包月天数 | E43: =E11 -> 42156 | F43: 42186 | G43: 42217 | H43: 42248 | I43: 42278 | J43: 42309
D44: 30 | F44: 174 | G44: 151 | H44: 230 | I44: 112 | J44: 141
D45: 90 | F45: 33 | G45: 26 | H45: 16 | I45: 14 | J45: 19
D46: 180 | F46: 7 | G46: 8 | H46: 5 | I46: 7 | J46: 7
D47: 360 | F47: 13 | G47: 6 | H47: 12 | I47: 9 | J47: 6
C49: VIP收入
C50: 摩尔庄园
D51: 包月天数 | E51: =E11 -> 42156 | F51: =F11 -> 42186 | G51: =G11 -> 42217 | H51: =H11 -> 42248 | I51: 42278 | J51: =J11 -> 42309
D52: 31 | E52: =E12*$B$3 -> 0 | F52: =F12*$B$3 -> 211050 | G52: =G12*$B$3 -> 177300 | H52: =H12*$B$3 -> 107250 | I52: =I12*$B$3 -> 91950
...

Sheet 数据-对账后分成收入
C1: 统一配置
C2: 各项目抽成比例
C3: 摩尔庄园 | D3: 0.18
C4: 赛尔号 | D4: 0.22
C5: 小花仙 | D5: 0.18
C6: 功夫派 | D6: 0.25
C7: 热血精灵派 | D7: 0.22
D9: 42156 | E9: 42186 | F9: 42217 | G9: 42248 | H9: 42278
C10: 本次美元汇率 | F10: 32.5 | H10: 32.44
C11: 本次人民币汇率
C16: 摩尔庄园 | D16: 42156 | E16: 42186 | F16: 42217 | G16: 42248 | H16: 42278 | I16: 42309
C17: 总收入 | F17: =数据—淘米方!G$124 -> 439485 | G17: =数据—淘米方!H$124 -> 324313 | H17: =数据—淘米方!I$124 -> 256149
C18: 测试收入 | F18: 7659 | G18: 7660 | H18: 2000
C19: 正式进账 | F19: =F17-F18 -> 431826 | G19: =G17-G18 -> 316653 | H19: =H17-H18 -> 254149
C20: 依据合约抽成 | F20: =ROUND(F19*$D$3,0) -> 77729 | G20: =ROUND(G19*$D$3,0) -> 56998 | H20: =ROUND(H19*$D$3,0) -> 45747
C21: 台湾政府税率20% | F21: =ROUND(F20*0.2,0) -> 15546 | G21: =ROUND(G20*0.2,0) -> 11400 | H21: =ROUND(H20*0.2,0) -> 9149
C22: 分成实付台币金额 | F22: =F20-F21 -> 62183 | G22: =G20-G21 -> 45598 | H22: =H20-H21 -> 36598
C23: 转成美金 | F23: =ROUND(F22/F10,2) -> 1913.32 | G23: =ROUND(G22/G10,2) -> #DIV/0! | H23: =ROUND(H22/H10,2) -> 1128.18
C24: 转成人民币
C26: 赛尔号 | D26: 42156 | E26: 42186 | F26: 42217 | G26: 42248 | H26: 42278 | I26: 42309
C27: 总收入 | F27: =数据—淘米方!G$125 -> 2131425 | H27: 1659395
C28: 测试收入 | F28: 5580 | H28: 15050
C29: 正式进账 | F29: =F27-F28 -> 2125845 | G29: =G27-G28 -> 0 | H29: =H27-H28 -> 1644345
C30: 依据合约抽成 | F30: =ROUND(F29*$D$4,0) -> 467686 | G30: =ROUND(G29*$D$4,0) -> 0 | H30: =ROUND(H29*$D$4,0) -> 361756
C31: 台湾政府税率20% | F31: =ROUND(F30*0.2,0) -> 93537 | G31: =ROUND(G30*0.2,0) -> 0 | H31: =ROUND(H30*0.2,0) -> 72351
C32: 分成实付台币金额 | F32: =F30-F31 -> 374149 | G32: =G30-G31 -> 0 | H32: =H30-H31 -> 289405
C33: 转成美金 | F33: =ROUND(F32/F$10,2) -> 11512.28 | G33: =ROUND(G32/G$10,2) -> #DIV/0! | H33: =ROUND(H32/H$10,2) -> 8921.24
C34: 转成人民币
C36: 小花仙 | D36: 42156 | E36: 42186 | F36: 42217 | G36: 42248 | H36: 42278 | I36: 42309
C37: 总收入 | F37: =数据—淘米方!G$126 -> 1451530 | H37: =数据—淘米方!I$126 -> 1025420
C38: 测试收入 | F38: 31695 | H38: 1555
C39: 正式进账 | F39: =F37-F38 -> 1419835 | H39: =H37-H38 -> 1023865
C40: 依据合约抽成 | F40: =ROUND(F39*$D$5,0) -> 255570 | H40: =ROUND(H39*$D$5,0) -> 184296
C41: 台湾政府税率20% | F41: =ROUND(F40*0.2,0) -> 51114 | H41: =ROUND(H40*0.2,0) -> 36859
C42: 分成实付台币金额 | F42: =F40-F41 -> 204456 | H42: =H40-H41 -> 147437
C43: 转成美金 | F43: =ROUND(F42/F$10,2) -> 6290.95 | H43: =ROUND(H42/H$10,2) -> 4544.91
C44: 转成人民币
C47: 功夫派 | D47: 42156 | E47: 42186 | F47: 42217 | G47: 42248 | H47: 42278 | I47: 42309
C48: 总收入 | F48: =数据—淘米方!G$127 -> 308395 | H48: 105735
C49: 测试收入 | F49: 13821 | H49: 1001
...
